Workbook
Name Roster: 'All-time'!$A$3:$A$30

Sheet README
B2: THAMESLINK HAJDUCI — TEAM TRACKER
B4: HOW IT WORKS
B5: Each season lives on ONE tab (S1–S6, S8). Everything for that season — fixtures, results, appearances, goals, assists, costs — is on that tab.
B6: Aggregator tabs (All-time, Money) sit after the season tabs and update automatically.
B7: Yellow cells are the weekly inputs: Our goals, Their goals, Match cost. Grey cells are calculated — don’t type in them.
B9: LOGGING A GAME (on the season tab)
B10: 1. Enter the score in the "Our goals" / "Their goals" rows (Score and W/D/L fill in automatically — this also permanently fixes the old problem of scores like 3-10 turning into dates).
B11: 2. Put a 1 in the APPEARANCES grid for everyone who played.
B12: 3. Enter goals/assists per player in the GOALS and ASSISTS grids.
B13: 4. Enter the Match cost (£). It’s split evenly across that game’s players and lands on each player’s Cost (£) column and the Money tab.
B15: MONEY
B16: All seasons before Season 8 are settled, so player tabs start from S8. The Money tab shows what each player has been charged (from the season tabs), what they’ve paid (from the Payments tab), and the balance they owe.
... B45: Season 8 fixtures loaded from playfootball.net (Whitechapel Tuesday 6’s, Premier League, "Season 2 2026") — 18 games, 1 Sep 2026 to 12 Jan 2027.

Sheet S1
A1: Season 1 · Play5aside Hoxton (sand, 5-a-side) · Sep–Nov 2024
A2: Match | B2: GW1 | C2: GW2 | D2: GW3 | E2: GW4 | F2: GW5 | G2: GW6 | H2: GW7 | I2: GW8 | J2: GW9 | K2: GW10 | L2: GW11 | M2: GW12 | N2: GW13 | O2: GW14 | P2: GW15 | Q2: GW16 | R2: GW17 | S2: GW18 | T2: GW19 | U2: GW20 | X2: SEASON SUMMARY
A3: Date | B3: 45546 | C3: 45553 | D3: 45560 | E3: 45567 | F3: 45574 | G3: 45581 | H3: 45588 | I3: 45595 | J3: 45602 | K3: 45609 | X3: Played | Y3: =Y4+Y5+Y6 -> 10
A4: Kick-off | X4: Won | Y4: =SUMPRODUCT(($B$9:$U$9="W")*($B$16:$U$16="")) -> 2
A5: Opponent | B5: MBS | C5: Barkways Sisters | D5: Safe FC | E5: Hardly Athletic | F5: Clapham Casuals | G5: MBS | H5: Barkways Sisters | I5: Safe FC | J5: Hardly Athletic | K5: Clapham Casuals | X5: Drawn | Y5: =SUMPRODUCT(($B$9:$U$9="D")*($B$16:$U$16="")) -> 1
A6: Our goals | B6: 3 | C6: 4 | D6: 1 | E6: 0 | F6: 1 | G6: 5 | H6: 3 | I6: 2 | J6: 3 | K6: 1 | X6: Lost | Y6: =SUMPRODUCT(($B$9:$U$9="L")*($B$16:$U$16="")) -> 7
A7: Their goals | B7: 11 | C7: 3 | D7: 5 | E7: 3 | F7: 2 | G7: 9 | H7: 3 | I7: 5 | J7: 2 | K7: 2 | X7: Goals for | Y7: =SUMPRODUCT($B$6:$U$6*($B$16:$U$16="")) -> 23
A8: Score | B8: =IF(COUNT(B6:B7)<2,"",B6&"-"&B7) -> 3-11 | C8: =IF(COUNT(C6:C7)<2,"",C6&"-"&C7) -> 4-3 | D8: =IF(COUNT(D6:D7)<2,"",D6&"-"&D7) -> 1-5 | E8: =IF(COUNT(E6:E7)<2,"",E6&"-"&E7) -> 0-3 | F8: =IF(COUNT(F6:F7)<2,"",F6&"-"&F7) -> 1-2 | G8: =IF(COUNT(G6:G7)<2,"",G6&"-"&G7) -> 5-9 | H8: =IF(COUNT(H6:H7)<2,"",H6&"-"&H7) -> 3-3 | I8: =IF(COUNT(I6:I7)<2,"",I6&"-"&I7) -> 2-5 | ... U8: =IF(COUNT(U6:U7)<2,"",U6&"-"&U7) | X8: Goals against | Y8: =SUMPRODUCT($B$7:$U$7*($B$16:$U$16="")) -> 45
A9: Result | B9: =IF(COUNT(B6:B7)<2,"",IF(B6>B7,"W",IF(B6<B7,"L","D"))) -> L | C9: =IF(COUNT(C6:C7)<2,"",IF(C6>C7,"W",IF(C6<C7,"L","D"))) -> W | D9: =IF(COUNT(D6:D7)<2,"",IF(D6>D7,"W",IF(D6<D7,"L","D"))) -> L | E9: =IF(COUNT(E6:E7)<2,"",IF(E6>E7,"W",IF(E6<E7,"L","D"))) -> L | F9: =IF(COUNT(F6:F7)<2,"",IF(F6>F7,"W",IF(F6<F7,"L","D"))) -> L | G9: =IF(COUNT(G6:G7)<2,"",IF(G6>G7,"W",IF(G6<G7,"L","D"))) -> L | H9: =IF(COUNT(H6:H7)<2,"",IF(H6>H7,"W",IF(H6<H7,"L","D"))) -> D | I9: =IF(COUNT(I6:I7)<2,"",IF(I6>I7,"W",IF(I6<I7,"L","D"))) -> L | ... U9: =IF(COUNT(U6:U7)<2,"",IF(U6>U7,"W",IF(U6<U7,"L","D"))) | X9: Top scorer | Y9: {=IF(MAX($V$49:$V$76)=0,"—",INDEX($A$49:$A$76,MATCH(MAX($V$49:$V$76),$V$49:$V$76,0))&" ("&MAX($V$49:$V$76)&")")} -> Sam Holt (5)
A10: MOTM | B10: Isaac Mond | C10: Callum McCarthy | D10: Phil Knott | E10: Henry Linklater | F10: Max Cobain | G10: Sam Holt | H10: Andy Cowan | I10: Phil Knott | J10: Sam Holt | K10: Isaac Mond | X10: Most apps | Y10: {=IF(MAX($V$18:$V$45)=0,"—",INDEX($A$18:$A$45,MATCH(MAX($V$18:$V$45),$V$18:$V$45,0))&" ("&MAX($V$18:$V$45)&")")} -> Phil Knott (10)
A11: Champagne moment | B11: Henry Linklater | C11: Max Cobain | E11: Max Cobain | F11: Abdul | H11: Ben Merrett | J11: Neeraj Radia | K11: Isaac Mond | X11: Season cost | Y11: =SUM($B$13:$U$13) -> 0
A12: Comments | C12: Phantom pullback | E12: "Anyone want to sub off" | F12: Tackled by his own teammate | H12: Shooting from kick off | J12: Claiming 4 assists | K12: 5 yard freekick | X12: Paid by
A13: Match cost (£)
A14: Players in game | B14: =COUNT(B$18:B$45) -> 6 | C14: =COUNT(C$18:C$45) -> 6 | D14: =COUNT(D$18:D$45) -> 5 | E14: =COUNT(E$18:E$45) -> 7 | F14: =COUNT(F$18:F$45) -> 7 | G14: =COUNT(G$18:G$45) -> 10 | H14: =COUNT(H$18:H$45) -> 7 | I14: =COUNT(I$18:I$45) -> 6 | ... U14: =COUNT(U$18:U$45) -> 0
A15: Cost per player (£) | B15: =IF(B$14=0,0,N(B$13)/B$14) -> 0 | C15: =IF(C$14=0,0,N(C$13)/C$14) -> 0 | D15: =IF(D$14=0,0,N(D$13)/D$14) -> 0 | E15: =IF(E$14=0,0,N(E$13)/E$14) -> 0 | F15: =IF(F$14=0,0,N(F$13)/F$14) -> 0 | G15: =IF(G$14=0,0,N(G$13)/G$14) -> 0 | H15: =IF(H$14=0,0,N(H$13)/H$14) -> 0 | I15: =IF(I$14=0,0,N(I$13)/I$14) -> 0 | ... U15: =IF(U$14=0,0,N(U$13)/U$14) -> 0
A16: Type (excl. from records)
A17: APPEARANCES (1 = played) | B17: GW1 | C17: GW2 | D17: GW3 | E17: GW4 | F17: GW5 | G17: GW6 | H17: GW7 | I17: GW8 | J17: GW9 | K17: GW10 | L17: GW11 | M17: GW12 | N17: GW13 | O17: GW14 | P17: GW15 | Q17: GW16 | R17: GW17 | S17: GW18 | T17: GW19 | U17: GW20 | V17: Apps | W17: Cost (£)
A18: Ahmed | V18: =SUMPRODUCT(B18:U18*($B$16:$U$16="")) -> 0 | W18: =SUMPRODUCT($B18:$U18,$B$15:$U$15) -> 0
A19: Alex Ruben | V19: =SUMPRODUCT(B19:U19*($B$16:$U$16="")) -> 0 | W19: =SUMPRODUCT($B19:$U19,$B$15:$U$15) -> 0
A20: Andy Cowan | D20: 1 | G20: 1 | H20: 1 | V20: =SUMPRODUCT(B20:U20*($B$16:$U$16="")) -> 3 | W20: =SUMPRODUCT($B20:$U20,$B$15:$U$15) -> 0
A21: Ben Merrett | F21: 1 | H21: 1 | I21: 1 | J21: 1 | K21: 1 | V21: =SUMPRODUCT(B21:U21*($B$16:$U$16="")) -> 5 | W21: =SUMPRODUCT($B21:$U21,$B$15:$U$15) -> 0
A22: Callum McCarthy | C22: 1 | E22: 1 | G22: 1 | V22: =SUMPRODUCT(B22:U22*($B$16:$U$16="")) -> 3 | W22: =SUMPRODUCT($B22:$U22,$B$15:$U$15) -> 0
A23: Cecil Watson | I23: 1 | J23: 1 | V23: =SUMPRODUCT(B23:U23*($B$16:$U$16="")) -> 2 | W23: =SUMPRODUCT($B23:$U23,$B$15:$U$15) -> 0
A24: Conall Templeman | V24: =SUMPRODUCT(B24:U24*($B$16:$U$16="")) -> 0 | W24: =SUMPRODUCT($B24:$U24,$B$15:$U$15) -> 0
A25: Eddie Ringer | V25: =SUMPRODUCT(B25:U25*($B$16:$U$16="")) -> 0 | W25: =SUMPRODUCT($B25:$U25,$B$15:$U$15) -> 0
A26: Finn Cawley | V26: =SUMPRODUCT(B26:U26*($B$16:$U$16="")) -> 0 | W26: =SUMPRODUCT($B26:$U26,$B$15:$U$15) -> 0
A27: George Barbantan | B27: 1 | C27: 1 | D27: 1 | G27: 1 | I27: 1 | V27: =SUMPRODUCT(B27:U27*($B$16:$U$16="")) -> 5 | W27: =SUMPRODUCT($B27:$U27,$B$15:$U$15) -> 0
A28: Henry Linklater | B28: 1 | C28: 1 | E28: 1 | F28: 1 | G28: 1 | H28: 1 | J28: 1 | K28: 1 | V28: =SUMPRODUCT(B28:U28*($B$16:$U$16="")) -> 8 | W28: =SUMPRODUCT($B28:$U28,$B$15:$U$15) -> 0
A29: Isaac Mond | B29: 1 | E29: 1 | F29: 1 | G29: 1 | H29: 1 | I29: 1 | J29: 1 | K29: 1 | V29: =SUMPRODUCT(B29:U29*($B$16:$U$16="")) -> 8 | W29: =SUMPRODUCT($B29:$U29,$B$15:$U$15) -> 0
A30: Jake Harrison | V30: =SUMPRODUCT(B30:U30*($B$16:$U$16="")) -> 0 | W30: =SUMPRODUCT($B30:$U30,$B$15:$U$15) -> 0
A31: Jake Ringer | V31: =SUMPRODUCT(B31:U31*($B$16:$U$16="")) -> 0 | W31: =SUMPRODUCT($B31:$U31,$B$15:$U$15) -> 0
A32: Keshav Singh | V32: =SUMPRODUCT(B32:U32*($B$16:$U$16="")) -> 0 | W32: =SUMPRODUCT($B32:$U32,$B$15:$U$15) -> 0
A33: Mark Pellowe | V33: =SUMPRODUCT(B33:U33*($B$16:$U$16="")) -> 0 | W33: =SUMPRODUCT($B33:$U33,$B$15:$U$15) -> 0
A34: Max Cobain | B34: 1 | C34: 1 | D34: 1 | E34: 1 | F34: 1 | G34: 1 | H34: 1 | K34: 1 | V34: =SUMPRODUCT(B34:U34*($B$16:$U$16="")) -> 8 | W34: =SUMPRODUCT($B34:$U34,$B$15:$U$15) -> 0
A35: Neeraj Radia | C35: 1 | D35: 1 | E35: 1 | F35: 1 | G35: 1 | H35: 1 | I35: 1 | J35: 1 | K35: 1 | V35: =SUMPRODUCT(B35:U35*($B$16:$U$16="")) -> 9 | W35: =SUMPRODUCT($B35:$U35,$B$15:$U$15) -> 0
A36: Phil Knott | B36: 1 | C36: 1 | D36: 1 | E36: 1 | F36: 1 | G36: 1 | H36: 1 | I36: 1 | J36: 1 | K36: 1 | V36: =SUMPRODUCT(B36:U36*($B$16:$U$16="")) -> 10 | W36: =SUMPRODUCT($B36:$U36,$B$15:$U$15) -> 0
A37: Robin | G37: 1 | V37: =SUMPRODUCT(B37:U37*($B$16:$U$16="")) -> 1 | W37: =SUMPRODUCT($B37:$U37,$B$15:$U$15) -> 0
A38: Sam Holt | B38: 1 | E38: 1 | F38: 1 | G38: 1 | J38: 1 | K38: 1 | V38: =SUMPRODUCT(B38:U38*($B$16:$U$16="")) -> 6 | W38: =SUMPRODUCT($B38:$U38,$B$15:$U$15) -> 0
A39: Seb Burgess | V39: =SUMPRODUCT(B39:U39*($B$16:$U$16="")) -> 0 | W39: =SUMPRODUCT($B39:$U39,$B$15:$U$15) -> 0
V40: =SUMPRODUCT(B40:U40*($B$16:$U$16="")) -> 0 | W40: =SUMPRODUCT($B40:$U40,$B$15:$U$15) -> 0
...

Sheet S2
A1: Season 2 · Powerleague Shoreditch (5G, 7-a-side) · Nov 2024–Jan 2025
A2: Match | B2: GW1 | C2: GW2 | D2: GW3 | E2: GW4 | F2: GW5 | G2: GW6 | H2: GW7 | I2: GW8 | J2: GW9 | K2: GW10 | L2: GW11 | M2: GW12 | N2: GW13 | O2: GW14 | P2: GW15 | Q2: GW16 | R2: GW17 | S2: GW18 | T2: GW19 | U2: GW20 | X2: SEASON SUMMARY
A3: Date | B3: 45624 | C3: 45631 | D3: 45638 | E3: 45645 | F3: 45666 | G3: 45673 | H3: 45680 | I3: 45687 | X3: Played | Y3: =Y4+Y5+Y6 -> 8
A4: Kick-off | X4: Won | Y4: =SUMPRODUCT(($B$9:$U$9="W")*($B$16:$U$16="")) -> 3
A5: Opponent | B5: Dalston Eagles | C5: Mutus | D5: LCG United | E5: Brighton | F5: City ACS | G5: Dalston | H5: Mutus | I5: LCG United | X5: Drawn | Y5: =SUMPRODUCT(($B$9:$U$9="D")*($B$16:$U$16="")) -> 0
A6: Our goals | B6: 3 | C6: 0 | D6: 2 | E6: 8 | F6: 4 | G6: 2 | H6: 2 | I6: 5 | X6: Lost | Y6: =SUMPRODUCT(($B$9:$U$9="L")*($B$16:$U$16="")) -> 5
A7: Their goals | B7: 10 | C7: 5 | D7: 5 | E7: 2 | F7: 3 | G7: 8 | H7: 11 | I7: 4 | X7: Goals for | Y7: =SUMPRODUCT($B$6:$U$6*($B$16:$U$16="")) -> 26
A8: Score | B8: =IF(COUNT(B6:B7)<2,"",B6&"-"&B7) -> 3-10 | C8: =IF(COUNT(C6:C7)<2,"",C6&"-"&C7) -> 0-5 | D8: =IF(COUNT(D6:D7)<2,"",D6&"-"&D7) -> 2-5 | E8: =IF(COUNT(E6:E7)<2,"",E6&"-"&E7) -> 8-2 | F8: =IF(COUNT(F6:F7)<2,"",F6&"-"&F7) -> 4-3 | G8: =IF(COUNT(G6:G7)<2,"",G6&"-"&G7) -> 2-8 | H8: =IF(COUNT(H6:H7)<2,"",H6&"-"&H7) -> 2-11 | I8: =IF(COUNT(I6:I7)<2,"",I6&"-"&I7) -> 5-4 | ... U8: =IF(COUNT(U6:U7)<2,"",U6&"-"&U7) | X8: Goals against | Y8: =SUMPRODUCT($B$7:$U$7*($B$16:$U$16="")) -> 48
A9: Result | B9: =IF(COUNT(B6:B7)<2,"",IF(B6>B7,"W",IF(B6<B7,"L","D"))) -> L | C9: =IF(COUNT(C6:C7)<2,"",IF(C6>C7,"W",IF(C6<C7,"L","D"))) -> L | D9: =IF(COUNT(D6:D7)<2,"",IF(D6>D7,"W",IF(D6<D7,"L","D"))) -> L | E9: =IF(COUNT(E6:E7)<2,"",IF(E6>E7,"W",IF(E6<E7,"L","D"))) -> W | F9: =IF(COUNT(F6:F7)<2,"",IF(F6>F7,"W",IF(F6<F7,"L","D"))) -> W | G9: =IF(COUNT(G6:G7)<2,"",IF(G6>G7,"W",IF(G6<G7,"L","D"))) -> L | H9: =IF(COUNT(H6:H7)<2,"",IF(H6>H7,"W",IF(H6<H7,"L","D"))) -> L | I9: =IF(COUNT(I6:I7)<2,"",IF(I6>I7,"W",IF(I6<I7,"L","D"))) -> W | ... U9: =IF(COUNT(U6:U7)<2,"",IF(U6>U7,"W",IF(U6<U7,"L","D"))) | X9: Top scorer | Y9: {=IF(MAX($V$49:$V$76)=0,"—",INDEX($A$49:$A$76,MATCH(MAX($V$49:$V$76),$V$49:$V$76,0))&" ("&MAX($V$49:$V$76)&")")} -> Seb Burgess (5)
A10: MOTM | B10: Sam Holt | C10: Henry Linklater | D10: Andy Cowan | E10: Finn Cawley | X10: Most apps | Y10: {=IF(MAX($V$18:$V$45)=0,"—",INDEX($A$18:$A$45,MATCH(MAX($V$18:$V$45),$V$18:$V$45,0))&" ("&MAX($V$18:$V$45)&")")} -> Andy Cowan (6)
A11: Champagne moment | X11: Season cost | Y11: =SUM($B$13:$U$13) -> 0
A12: Comments | X12: Paid by
A13: Match cost (£)
A14: Players in game | B14: =COUNT(B$18:B$45) -> 7 | C14: =COUNT(C$18:C$45) -> 8 | D14: =COUNT(D$18:D$45) -> 7 | E14: =COUNT(E$18:E$45) -> 4 | F14: =COUNT(F$18:F$45) -> 9 | G14: =COUNT(G$18:G$45) -> 8 | H14: =COUNT(H$18:H$45) -> 6 | I14: =COUNT(I$18:I$45) -> 7 | ... U14: =COUNT(U$18:U$45) -> 0
A15: Cost per player (£) | B15: =IF(B$14=0,0,N(B$13)/B$14) -> 0 | C15: =IF(C$14=0,0,N(C$13)/C$14) -> 0 | D15: =IF(D$14=0,0,N(D$13)/D$14) -> 0 | E15: =IF(E$14=0,0,N(E$13)/E$14) -> 0 | F15: =IF(F$14=0,0,N(F$13)/F$14) -> 0 | G15: =IF(G$14=0,0,N(G$13)/G$14) -> 0 | H15: =IF(H$14=0,0,N(H$13)/H$14) -> 0 | I15: =IF(I$14=0,0,N(I$13)/I$14) -> 0 | ... U15: =IF(U$14=0,0,N(U$13)/U$14) -> 0
A16: Type (excl. from records)
A17: APPEARANCES (1 = played) | B17: GW1 | C17: GW2 | D17: GW3 | E17: GW4 | F17: GW5 | G17: GW6 | H17: GW7 | I17: GW8 | J17: GW9 | K17: GW10 | L17: GW11 | M17: GW12 | N17: GW13 | O17: GW14 | P17: GW15 | Q17: GW16 | R17: GW17 | S17: GW18 | T17: GW19 | U17: GW20 | V17: Apps | W17: Cost (£)
A18: Ahmed | V18: =SUMPRODUCT(B18:U18*($B$16:$U$16="")) -> 0 | W18: =SUMPRODUCT($B18:$U18,$B$15:$U$15) -> 0
A19: Alex Ruben | H19: 1 | V19: =SUMPRODUCT(B19:U19*($B$16:$U$16="")) -> 1 | W19: =SUMPRODUCT($B19:$U19,$B$15:$U$15) -> 0
A20: Andy Cowan | B20: 1 | C20: 1 | D20: 1 | F20: 1 | G20: 1 | I20: 1 | V20: =SUMPRODUCT(B20:U20*($B$16:$U$16="")) -> 6 | W20: =SUMPRODUCT($B20:$U20,$B$15:$U$15) -> 0
A21: Ben Merrett | D21: 1 | F21: 1 | G21: 1 | H21: 1 | V21: =SUMPRODUCT(B21:U21*($B$16:$U$16="")) -> 4 | W21: =SUMPRODUCT($B21:$U21,$B$15:$U$15) -> 0
A22: Callum McCarthy | B22: 1 | C22: 1 | V22: =SUMPRODUCT(B22:U22*($B$16:$U$16="")) -> 2 | W22: =SUMPRODUCT($B22:$U22,$B$15:$U$15) -> 0
A23: Cecil Watson | V23: =SUMPRODUCT(B23:U23*($B$16:$U$16="")) -> 0 | W23: =SUMPRODUCT($B23:$U23,$B$15:$U$15) -> 0
A24: Conall Templeman | V24: =SUMPRODUCT(B24:U24*($B$16:$U$16="")) -> 0 | W24: =SUMPRODUCT($B24:$U24,$B$15:$U$15) -> 0
A25: Eddie Ringer | V25: =SUMPRODUCT(B25:U25*($B$16:$U$16="")) -> 0 | W25: =SUMPRODUCT($B25:$U25,$B$15:$U$15) -> 0
A26: Finn Cawley | E26: 1 | F26: 1 | G26: 1 | I26: 1 | V26: =SUMPRODUCT(B26:U26*($B$16:$U$16="")) -> 4 | W26: =SUMPRODUCT($B26:$U26,$B$15:$U$15) -> 0
A27: George Barbantan | C27: 1 | D27: 1 | F27: 1 | H27: 1 | I27: 1 | V27: =SUMPRODUCT(B27:U27*($B$16:$U$16="")) -> 5 | W27: =SUMPRODUCT($B27:$U27,$B$15:$U$15) -> 0
A28: Henry Linklater | B28: 1 | C28: 1 | E28: 1 | G28: 1 | H28: 1 | I28: 1 | V28: =SUMPRODUCT(B28:U28*($B$16:$U$16="")) -> 6 | W28: =SUMPRODUCT($B28:$U28,$B$15:$U$15) -> 0
A29: Isaac Mond | B29: 1 | D29: 1 | F29: 1 | V29: =SUMPRODUCT(B29:U29*($B$16:$U$16="")) -> 3 | W29: =SUMPRODUCT($B29:$U29,$B$15:$U$15) -> 0
A30: Jake Harrison | F30: 1 | V30: =SUMPRODUCT(B30:U30*($B$16:$U$16="")) -> 1 | W30: =SUMPRODUCT($B30:$U30,$B$15:$U$15) -> 0
A31: Jake Ringer | V31: =SUMPRODUCT(B31:U31*($B$16:$U$16="")) -> 0 | W31: =SUMPRODUCT($B31:$U31,$B$15:$U$15) -> 0
A32: Keshav Singh | V32: =SUMPRODUCT(B32:U32*($B$16:$U$16="")) -> 0 | W32: =SUMPRODUCT($B32:$U32,$B$15:$U$15) -> 0
A33: Mark Pellowe | V33: =SUMPRODUCT(B33:U33*($B$16:$U$16="")) -> 0 | W33: =SUMPRODUCT($B33:$U33,$B$15:$U$15) -> 0
A34: Max Cobain | D34: 1 | F34: 1 | G34: 1 | H34: 1 | I34: 1 | V34: =SUMPRODUCT(B34:U34*($B$16:$U$16="")) -> 5 | W34: =SUMPRODUCT($B34:$U34,$B$15:$U$15) -> 0
A35: Neeraj Radia | C35: 1 | F35: 1 | G35: 1 | V35: =SUMPRODUCT(B35:U35*($B$16:$U$16="")) -> 3 | W35: =SUMPRODUCT($B35:$U35,$B$15:$U$15) -> 0
A36: Phil Knott | B36: 1 | C36: 1 | D36: 1 | E36: 1 | V36: =SUMPRODUCT(B36:U36*($B$16:$U$16="")) -> 4 | W36: =SUMPRODUCT($B36:$U36,$B$15:$U$15) -> 0
A37: Robin | C37: 1 | V37: =SUMPRODUCT(B37:U37*($B$16:$U$16="")) -> 1 | W37: =SUMPRODUCT($B37:$U37,$B$15:$U$15) -> 0
A38: Sam Holt | B38: 1 | D38: 1 | F38: 1 | G38: 1 | H38: 1 | I38: 1 | V38: =SUMPRODUCT(B38:U38*($B$16:$U$16="")) -> 6 | W38: =SUMPRODUCT($B38:$U38,$B$15:$U$15) -> 0
A39: Seb Burgess | B39: 1 | C39: 1 | E39: 1 | G39: 1 | I39: 1 | V39: =SUMPRODUCT(B39:U39*($B$16:$U$16="")) -> 5 | W39: =SUMPRODUCT($B39:$U39,$B$15:$U$15) -> 0
V40: =SUMPRODUCT(B40:U40*($B$16:$U$16="")) -> 0 | W40: =SUMPRODUCT($B40:$U40,$B$15:$U$15) -> 0
...

Sheet S3
A1: Season 3 · PlayFootball Old Street (5G, 6-a-side) · Mar–Jun 2025
A2: Match | B2: GW1 | C2: GW2 | D2: GW3 | E2: GW4 | F2: GW5 | G2: GW6 | H2: GW7 | I2: GW8 | J2: GW9 | K2: GW10 | L2: GW11 | M2: GW12 | N2: GW13 | O2: GW14 | P2: GW15 | Q2: GW16 | R2: GW17 | S2: GW18 | T2: GW19 | U2: GW20 | X2: SEASON SUMMARY
A3: Date | B3: 45742 | C3: 45743 | D3: 45750 | E3: 45757 | F3: 45764 | G3: 45771 | H3: 45778 | I3: 45785 | J3: 45792 | K3: 45799 | L3: 45806 | M3: 45813 | N3: 45820 | O3: 45827 | X3: Played | Y3: =Y4+Y5+Y6 -> 13
A4: Kick-off | X4: Won | Y4: =SUMPRODUCT(($B$9:$U$9="W")*($B$16:$U$16="")) -> 1
A5: Opponent | B5: Forfeit | C5: Enjoy your Mane Jane | D5: Dukes Select | E5: Dign Cats | F5: Old Ivy | G5: Green of the South | H5: The Britannias | I5: Spudos | J5: Old Ivy | K5: Green of the South | L5: Ding cats | M5: The Britannias | N5: Dukes Select | O5: Enjoy your Mane Jane | X5: Drawn | Y5: =SUMPRODUCT(($B$9:$U$9="D")*($B$16:$U$16="")) -> 1
A6: Our goals | B6: 8 | C6: 2 | D6: 1 | E6: 2 | F6: 4 | G6: 2 | H6: 1 | I6: 10 | J6: 3 | K6: 3 | L6: 1 | M6: 2 | N6: 3 | O6: 1 | X6: Lost | Y6: =SUMPRODUCT(($B$9:$U$9="L")*($B$16:$U$16="")) -> 11
A7: Their goals | B7: 0 | C7: 11 | D7: 7 | E7: 6 | F7: 8 | G7: 5 | H7: 4 | I7: 0 | J7: 9 | K7: 13 | L7: 6 | M7: 13 | N7: 3 | O7: 12 | X7: Goals for | Y7: =SUMPRODUCT($B$6:$U$6*($B$16:$U$16="")) -> 35
A8: Score | B8: =IF(COUNT(B6:B7)<2,"",B6&"-"&B7) -> 8-0 | C8: =IF(COUNT(C6:C7)<2,"",C6&"-"&C7) -> 2-11 | D8: =IF(COUNT(D6:D7)<2,"",D6&"-"&D7) -> 1-7 | E8: =IF(COUNT(E6:E7)<2,"",E6&"-"&E7) -> 2-6 | F8: =IF(COUNT(F6:F7)<2,"",F6&"-"&F7) -> 4-8 | G8: =IF(COUNT(G6:G7)<2,"",G6&"-"&G7) -> 2-5 | H8: =IF(COUNT(H6:H7)<2,"",H6&"-"&H7) -> 1-4 | I8: =IF(COUNT(I6:I7)<2,"",I6&"-"&I7) -> 10-0 | ... U8: =IF(COUNT(U6:U7)<2,"",U6&"-"&U7) | X8: Goals against | Y8: =SUMPRODUCT($B$7:$U$7*($B$16:$U$16="")) -> 97
A9: Result | B9: =IF(COUNT(B6:B7)<2,"",IF(B6>B7,"W",IF(B6<B7,"L","D"))) -> W | C9: =IF(COUNT(C6:C7)<2,"",IF(C6>C7,"W",IF(C6<C7,"L","D"))) -> L | D9: =IF(COUNT(D6:D7)<2,"",IF(D6>D7,"W",IF(D6<D7,"L","D"))) -> L | E9: =IF(COUNT(E6:E7)<2,"",IF(E6>E7,"W",IF(E6<E7,"L","D"))) -> L | F9: =IF(COUNT(F6:F7)<2,"",IF(F6>F7,"W",IF(F6<F7,"L","D"))) -> L | G9: =IF(COUNT(G6:G7)<2,"",IF(G6>G7,"W",IF(G6<G7,"L","D"))) -> L | H9: =IF(COUNT(H6:H7)<2,"",IF(H6>H7,"W",IF(H6<H7,"L","D"))) -> L | I9: =IF(COUNT(I6:I7)<2,"",IF(I6>I7,"W",IF(I6<I7,"L","D"))) -> W | ... U9: =IF(COUNT(U6:U7)<2,"",IF(U6>U7,"W",IF(U6<U7,"L","D"))) | X9: Top scorer | Y9: {=IF(MAX($V$49:$V$76)=0,"—",INDEX($A$49:$A$76,MATCH(MAX($V$49:$V$76),$V$49:$V$76,0))&" ("&MAX($V$49:$V$76)&")")} -> Phil Knott (7)
A10: MOTM | X10: Most apps | Y10: {=IF(MAX($V$18:$V$45)=0,"—",INDEX($A$18:$A$45,MATCH(MAX($V$18:$V$45),$V$18:$V$45,0))&" ("&MAX($V$18:$V$45)&")")} -> Andy Cowan (10)
A11: Champagne moment | X11: Season cost | Y11: =SUM($B$13:$U$13) -> 0
A12: Comments | X12: Paid by
A13: Match cost (£)
A14: Players in game | B14: =COUNT(B$18:B$45) -> 0 | C14: =COUNT(C$18:C$45) -> 6 | D14: =COUNT(D$18:D$45) -> 8 | E14: =COUNT(E$18:E$45) -> 6 | F14: =COUNT(F$18:F$45) -> 7 | G14: =COUNT(G$18:G$45) -> 7 | H14: =COUNT(H$18:H$45) -> 8 | I14: =COUNT(I$18:I$45) -> 8 | ... U14: =COUNT(U$18:U$45) -> 0
A15: Cost per player (£) | B15: =IF(B$14=0,0,N(B$13)/B$14) -> 0 | C15: =IF(C$14=0,0,N(C$13)/C$14) -> 0 | D15: =IF(D$14=0,0,N(D$13)/D$14) -> 0 | E15: =IF(E$14=0,0,N(E$13)/E$14) -> 0 | F15: =IF(F$14=0,0,N(F$13)/F$14) -> 0 | G15: =IF(G$14=0,0,N(G$13)/G$14) -> 0 | H15: =IF(H$14=0,0,N(H$13)/H$14) -> 0 | I15: =IF(I$14=0,0,N(I$13)/I$14) -> 0 | ... U15: =IF(U$14=0,0,N(U$13)/U$14) -> 0
A16: Type (excl. from records) | B16: Forfeit
A17: APPEARANCES (1 = played) | B17: GW1 | C17: GW2 | D17: GW3 | E17: GW4 | F17: GW5 | G17: GW6 | H17: GW7 | I17: GW8 | J17: GW9 | K17: GW10 | L17: GW11 | M17: GW12 | N17: GW13 | O17: GW14 | P17: GW15 | Q17: GW16 | R17: GW17 | S17: GW18 | T17: GW19 | U17: GW20 | V17: Apps | W17: Cost (£)
A18: Ahmed | V18: =SUMPRODUCT(B18:U18*($B$16:$U$16="")) -> 0 | W18: =SUMPRODUCT($B18:$U18,$B$15:$U$15) -> 0
A19: Alex Ruben | K19: 1 | O19: 1 | V19: =SUMPRODUCT(B19:U19*($B$16:$U$16="")) -> 2 | W19: =SUMPRODUCT($B19:$U19,$B$15:$U$15) -> 0
A20: Andy Cowan | C20: 1 | E20: 1 | F20: 1 | G20: 1 | I20: 1 | K20: 1 | L20: 1 | M20: 1 | N20: 1 | O20: 1 | V20: =SUMPRODUCT(B20:U20*($B$16:$U$16="")) -> 10 | W20: =SUMPRODUCT($B20:$U20,$B$15:$U$15) -> 0
A21: Ben Merrett | D21: 1 | F21: 1 | G21: 1 | H21: 1 | I21: 1 | K21: 1 | L21: 1 | N21: 1 | V21: =SUMPRODUCT(B21:U21*($B$16:$U$16="")) -> 8 | W21: =SUMPRODUCT($B21:$U21,$B$15:$U$15) -> 0
A22: Callum McCarthy | D22: 1 | E22: 1 | H22: 1 | I22: 1 | J22: 1 | L22: 1 | N22: 1 | V22: =SUMPRODUCT(B22:U22*($B$16:$U$16="")) -> 7 | W22: =SUMPRODUCT($B22:$U22,$B$15:$U$15) -> 0
A23: Cecil Watson | J23: 1 | V23: =SUMPRODUCT(B23:U23*($B$16:$U$16="")) -> 1 | W23: =SUMPRODUCT($B23:$U23,$B$15:$U$15) -> 0
A24: Conall Templeman | V24: =SUMPRODUCT(B24:U24*($B$16:$U$16="")) -> 0 | W24: =SUMPRODUCT($B24:$U24,$B$15:$U$15) -> 0
A25: Eddie Ringer | V25: =SUMPRODUCT(B25:U25*($B$16:$U$16="")) -> 0 | W25: =SUMPRODUCT($B25:$U25,$B$15:$U$15) -> 0
A26: Finn Cawley | C26: 1 | D26: 1 | E26: 1 | I26: 1 | K26: 1 | M26: 1 | O26: 1 | V26: =SUMPRODUCT(B26:U26*($B$16:$U$16="")) -> 7 | W26: =SUMPRODUCT($B26:$U26,$B$15:$U$15) -> 0
A27: George Barbantan | F27: 1 | H27: 1 | I27: 1 | J27: 1 | K27: 1 | V27: =SUMPRODUCT(B27:U27*($B$16:$U$16="")) -> 5 | W27: =SUMPRODUCT($B27:$U27,$B$15:$U$15) -> 0
A28: Henry Linklater | C28: 1 | J28: 1 | V28: =SUMPRODUCT(B28:U28*($B$16:$U$16="")) -> 2 | W28: =SUMPRODUCT($B28:$U28,$B$15:$U$15) -> 0
A29: Isaac Mond | C29: 1 | D29: 1 | E29: 1 | F29: 1 | G29: 1 | H29: 1 | I29: 1 | K29: 1 | L29: 1 | N29: 1 | V29: =SUMPRODUCT(B29:U29*($B$16:$U$16="")) -> 10 | W29: =SUMPRODUCT($B29:$U29,$B$15:$U$15) -> 0
A30: Jake Harrison | V30: =SUMPRODUCT(B30:U30*($B$16:$U$16="")) -> 0 | W30: =SUMPRODUCT($B30:$U30,$B$15:$U$15) -> 0
A31: Jake Ringer | V31: =SUMPRODUCT(B31:U31*($B$16:$U$16="")) -> 0 | W31: =SUMPRODUCT($B31:$U31,$B$15:$U$15) -> 0
A32: Keshav Singh | V32: =SUMPRODUCT(B32:U32*($B$16:$U$16="")) -> 0 | W32: =SUMPRODUCT($B32:$U32,$B$15:$U$15) -> 0
A33: Mark Pellowe | V33: =SUMPRODUCT(B33:U33*($B$16:$U$16="")) -> 0 | W33: =SUMPRODUCT($B33:$U33,$B$15:$U$15) -> 0
A34: Max Cobain | C34: 1 | D34: 1 | F34: 1 | G34: 1 | H34: 1 | J34: 1 | M34: 1 | O34: 1 | V34: =SUMPRODUCT(B34:U34*($B$16:$U$16="")) -> 8 | W34: =SUMPRODUCT($B34:$U34,$B$15:$U$15) -> 0
A35: Neeraj Radia | D35: 1 | F35: 1 | G35: 1 | H35: 1 | I35: 1 | J35: 1 | L35: 1 | V35: =SUMPRODUCT(B35:U35*($B$16:$U$16="")) -> 7 | W35: =SUMPRODUCT($B35:$U35,$B$15:$U$15) -> 0
A36: Phil Knott | D36: 1 | E36: 1 | G36: 1 | H36: 1 | I36: 1 | K36: 1 | L36: 1 | N36: 1 | O36: 1 | V36: =SUMPRODUCT(B36:U36*($B$16:$U$16="")) -> 9 | W36: =SUMPRODUCT($B36:$U36,$B$15:$U$15) -> 0
A37: Robin | V37: =SUMPRODUCT(B37:U37*($B$16:$U$16="")) -> 0 | W37: =SUMPRODUCT($B37:$U37,$B$15:$U$15) -> 0
A38: Sam Holt | C38: 1 | V38: =SUMPRODUCT(B38:U38*($B$16:$U$16="")) -> 1 | W38: =SUMPRODUCT($B38:$U38,$B$15:$U$15) -> 0
A39: Seb Burgess | D39: 1 | E39: 1 | F39: 1 | G39: 1 | H39: 1 | K39: 1 | L39: 1 | M39: 1 | N39: 1 | V39: =SUMPRODUCT(B39:U39*($B$16:$U$16="")) -> 9 | W39: =SUMPRODUCT($B39:$U39,$B$15:$U$15) -> 0
V40: =SUMPRODUCT(B40:U40*($B$16:$U$16="")) -> 0 | W40: =SUMPRODUCT($B40:$U40,$B$15:$U$15) -> 0
...

Sheet S4
A1: Season 4 · PlayFootball Old Street (5G, 6-a-side) · Jul–Oct 2025
A2: Match | B2: GW1 | C2: GW2 | D2: GW3 | E2: GW4 | F2: GW5 | G2: GW6 | H2: GW7 | I2: GW8 | J2: GW9 | K2: GW10 | L2: GW11 | M2: GW12 | N2: GW13 | O2: GW14 | P2: GW15 | Q2: GW16 | R2: GW17 | S2: GW18 | T2: GW19 | U2: GW20 | X2: SEASON SUMMARY
A3: Date | B3: 45841 | C3: 45848 | D3: 45855 | E3: 45862 | F3: 45869 | G3: 45876 | H3: 45883 | I3: 45890 | J3: 45897 | K3: 45904 | L3: 45911 | M3: 45918 | N3: 45925 | O3: 45932 | X3: Played | Y3: =Y4+Y5+Y6 -> 11
A4: Kick-off | X4: Won | Y4: =SUMPRODUCT(($B$9:$U$9="W")*($B$16:$U$16="")) -> 2
A5: Opponent | B5: Dukes Select | C5: Ding Cats | D5: Green of the South | E5: Enjoy your Mane Jane | F5: Old Ivy | G5: Spudos FC | H5: The Britannias | I5: DingCats | J5: Dukes Select | K5: Old ivy | L5: Spudos | M5: Enjoy your mane Jane | N5: The Britannias | O5: Green of the South | X5: Drawn | Y5: =SUMPRODUCT(($B$9:$U$9="D")*($B$16:$U$16="")) -> 0
A6: Our goals | B6: 3 | C6: 2 | D6: 4 | E6: 4 | F6: 2 | G6: 2 | H6: 4 | I6: 2 | L6: 5 | N6: 0 | O6: 2 | X6: Lost | Y6: =SUMPRODUCT(($B$9:$U$9="L")*($B$16:$U$16="")) -> 9
A7: Their goals | B7: 8 | C7: 7 | D7: 8 | E7: 7 | F7: 6 | G7: 7 | H7: 3 | I7: 6 | L7: 1 | N7: 3 | O7: 4 | X7: Goals for | Y7: =SUMPRODUCT($B$6:$U$6*($B$16:$U$16="")) -> 30
A8: Score | B8: =IF(COUNT(B6:B7)<2,"",B6&"-"&B7) -> 3-8 | C8: =IF(COUNT(C6:C7)<2,"",C6&"-"&C7) -> 2-7 | D8: =IF(COUNT(D6:D7)<2,"",D6&"-"&D7) -> 4-8 | E8: =IF(COUNT(E6:E7)<2,"",E6&"-"&E7) -> 4-7 | F8: =IF(COUNT(F6:F7)<2,"",F6&"-"&F7) -> 2-6 | G8: =IF(COUNT(G6:G7)<2,"",G6&"-"&G7) -> 2-7 | H8: =IF(COUNT(H6:H7)<2,"",H6&"-"&H7) -> 4-3 | I8: =IF(COUNT(I6:I7)<2,"",I6&"-"&I7) -> 2-6 | ... U8: =IF(COUNT(U6:U7)<2,"",U6&"-"&U7) | X8: Goals against | Y8: =SUMPRODUCT($B$7:$U$7*($B$16:$U$16="")) -> 60
A9: Result | B9: =IF(COUNT(B6:B7)<2,"",IF(B6>B7,"W",IF(B6<B7,"L","D"))) -> L | C9: =IF(COUNT(C6:C7)<2,"",IF(C6>C7,"W",IF(C6<C7,"L","D"))) -> L | D9: =IF(COUNT(D6:D7)<2,"",IF(D6>D7,"W",IF(D6<D7,"L","D"))) -> L | E9: =IF(COUNT(E6:E7)<2,"",IF(E6>E7,"W",IF(E6<E7,"L","D"))) -> L | F9: =IF(COUNT(F6:F7)<2,"",IF(F6>F7,"W",IF(F6<F7,"L","D"))) -> L | G9: =IF(COUNT(G6:G7)<2,"",IF(G6>G7,"W",IF(G6<G7,"L","D"))) -> L | H9: =IF(COUNT(H6:H7)<2,"",IF(H6>H7,"W",IF(H6<H7,"L","D"))) -> W | I9: =IF(COUNT(I6:I7)<2,"",IF(I6>I7,"W",IF(I6<I7,"L","D"))) -> L | ... U9: =IF(COUNT(U6:U7)<2,"",IF(U6>U7,"W",IF(U6<U7,"L","D"))) | X9: Top scorer | Y9: {=IF(MAX($V$49:$V$76)=0,"—",INDEX($A$49:$A$76,MATCH(MAX($V$49:$V$76),$V$49:$V$76,0))&" ("&MAX($V$49:$V$76)&")")} -> Seb Burgess (14)
A10: MOTM | B10: Phil Knott | X10: Most apps | Y10: {=IF(MAX($V$18:$V$45)=0,"—",INDEX($A$18:$A$45,MATCH(MAX($V$18:$V$45),$V$18:$V$45,0))&" ("&MAX($V$18:$V$45)&")")} -> Seb Burgess (13)
A11: Champagne moment | X11: Season cost | Y11: =SUM($B$13:$U$13) -> 0
A12: Comments | J12: score not recorded | K12: score not recorded | M12: score not recorded | X12: Paid by
A13: Match cost (£)
A14: Players in game | B14: =COUNT(B$18:B$45) -> 5 | C14: =COUNT(C$18:C$45) -> 7 | D14: =COUNT(D$18:D$45) -> 6 | E14: =COUNT(E$18:E$45) -> 7 | F14: =COUNT(F$18:F$45) -> 6 | G14: =COUNT(G$18:G$45) -> 7 | H14: =COUNT(H$18:H$45) -> 5 | I14: =COUNT(I$18:I$45) -> 6 | ... U14: =COUNT(U$18:U$45) -> 0
A15: Cost per player (£) | B15: =IF(B$14=0,0,N(B$13)/B$14) -> 0 | C15: =IF(C$14=0,0,N(C$13)/C$14) -> 0 | D15: =IF(D$14=0,0,N(D$13)/D$14) -> 0 | E15: =IF(E$14=0,0,N(E$13)/E$14) -> 0 | F15: =IF(F$14=0,0,N(F$13)/F$14) -> 0 | G15: =IF(G$14=0,0,N(G$13)/G$14) -> 0 | H15: =IF(H$14=0,0,N(H$13)/H$14) -> 0 | I15: =IF(I$14=0,0,N(I$13)/I$14) -> 0 | ... U15: =IF(U$14=0,0,N(U$13)/U$14) -> 0
A16: Type (excl. from records)
A17: APPEARANCES (1 = played) | B17: GW1 | C17: GW2 | D17: GW3 | E17: GW4 | F17: GW5 | G17: GW6 | H17: GW7 | I17: GW8 | J17: GW9 | K17: GW10 | L17: GW11 | M17: GW12 | N17: GW13 | O17: GW14 | P17: GW15 | Q17: GW16 | R17: GW17 | S17: GW18 | T17: GW19 | U17: GW20 | V17: Apps | W17: Cost (£)
A18: Ahmed | V18: =SUMPRODUCT(B18:U18*($B$16:$U$16="")) -> 0 | W18: =SUMPRODUCT($B18:$U18,$B$15:$U$15) -> 0
A19: Alex Ruben | D19: 1 | V19: =SUMPRODUCT(B19:U19*($B$16:$U$16="")) -> 1 | W19: =SUMPRODUCT($B19:$U19,$B$15:$U$15) -> 0
A20: Andy Cowan | B20: 1 | C20: 1 | F20: 1 | H20: 1 | J20: 1 | K20: 1 | L20: 1 | N20: 1 | O20: 1 | V20: =SUMPRODUCT(B20:U20*($B$16:$U$16="")) -> 9 | W20: =SUMPRODUCT($B20:$U20,$B$15:$U$15) -> 0
A21: Ben Merrett | C21: 1 | D21: 1 | E21: 1 | I21: 1 | J21: 1 | K21: 1 | L21: 1 | M21: 1 | V21: =SUMPRODUCT(B21:U21*($B$16:$U$16="")) -> 8 | W21: =SUMPRODUCT($B21:$U21,$B$15:$U$15) -> 0
A22: Callum McCarthy | B22: 1 | D22: 1 | H22: 1 | J22: 1 | K22: 1 | L22: 1 | V22: =SUMPRODUCT(B22:U22*($B$16:$U$16="")) -> 6 | W22: =SUMPRODUCT($B22:$U22,$B$15:$U$15) -> 0
A23: Cecil Watson | E23: 1 | V23: =SUMPRODUCT(B23:U23*($B$16:$U$16="")) -> 1 | W23: =SUMPRODUCT($B23:$U23,$B$15:$U$15) -> 0
A24: Conall Templeman | V24: =SUMPRODUCT(B24:U24*($B$16:$U$16="")) -> 0 | W24: =SUMPRODUCT($B24:$U24,$B$15:$U$15) -> 0
A25: Eddie Ringer | V25: =SUMPRODUCT(B25:U25*($B$16:$U$16="")) -> 0 | W25: =SUMPRODUCT($B25:$U25,$B$15:$U$15) -> 0
A26: Finn Cawley | C26: 1 | E26: 1 | G26: 1 | I26: 1 | V26: =SUMPRODUCT(B26:U26*($B$16:$U$16="")) -> 4 | W26: =SUMPRODUCT($B26:$U26,$B$15:$U$15) -> 0
A27: George Barbantan | D27: 1 | E27: 1 | F27: 1 | G27: 1 | H27: 1 | I27: 1 | J27: 1 | N27: 1 | O27: 1 | V27: =SUMPRODUCT(B27:U27*($B$16:$U$16="")) -> 9 | W27: =SUMPRODUCT($B27:$U27,$B$15:$U$15) -> 0
A28: Henry Linklater | V28: =SUMPRODUCT(B28:U28*($B$16:$U$16="")) -> 0 | W28: =SUMPRODUCT($B28:$U28,$B$15:$U$15) -> 0
A29: Isaac Mond | C29: 1 | F29: 1 | G29: 1 | J29: 1 | K29: 1 | L29: 1 | M29: 1 | N29: 1 | O29: 1 | V29: =SUMPRODUCT(B29:U29*($B$16:$U$16="")) -> 9 | W29: =SUMPRODUCT($B29:$U29,$B$15:$U$15) -> 0
A30: Jake Harrison | V30: =SUMPRODUCT(B30:U30*($B$16:$U$16="")) -> 0 | W30: =SUMPRODUCT($B30:$U30,$B$15:$U$15) -> 0
A31: Jake Ringer | V31: =SUMPRODUCT(B31:U31*($B$16:$U$16="")) -> 0 | W31: =SUMPRODUCT($B31:$U31,$B$15:$U$15) -> 0
A32: Keshav Singh | V32: =SUMPRODUCT(B32:U32*($B$16:$U$16="")) -> 0 | W32: =SUMPRODUCT($B32:$U32,$B$15:$U$15) -> 0
A33: Mark Pellowe | V33: =SUMPRODUCT(B33:U33*($B$16:$U$16="")) -> 0 | W33: =SUMPRODUCT($B33:$U33,$B$15:$U$15) -> 0
A34: Max Cobain | B34: 1 | C34: 1 | D34: 1 | G34: 1 | I34: 1 | K34: 1 | M34: 1 | N34: 1 | V34: =SUMPRODUCT(B34:U34*($B$16:$U$16="")) -> 8 | W34: =SUMPRODUCT($B34:$U34,$B$15:$U$15) -> 0
A35: Neeraj Radia | C35: 1 | E35: 1 | F35: 1 | G35: 1 | H35: 1 | I35: 1 | J35: 1 | K35: 1 | L35: 1 | V35: =SUMPRODUCT(B35:U35*($B$16:$U$16="")) -> 9 | W35: =SUMPRODUCT($B35:$U35,$B$15:$U$15) -> 0
A36: Phil Knott | B36: 1 | E36: 1 | F36: 1 | G36: 1 | L36: 1 | V36: =SUMPRODUCT(B36:U36*($B$16:$U$16="")) -> 5 | W36: =SUMPRODUCT($B36:$U36,$B$15:$U$15) -> 0
A37: Robin | V37: =SUMPRODUCT(B37:U37*($B$16:$U$16="")) -> 0 | W37: =SUMPRODUCT($B37:$U37,$B$15:$U$15) -> 0
A38: Sam Holt | M38: 1 | N38: 1 | O38: 1 | V38: =SUMPRODUCT(B38:U38*($B$16:$U$16="")) -> 3 | W38: =SUMPRODUCT($B38:$U38,$B$15:$U$15) -> 0
A39: Seb Burgess | B39: 1 | C39: 1 | D39: 1 | E39: 1 | F39: 1 | G39: 1 | H39: 1 | I39: 1 | K39: 1 | L39: 1 | M39: 1 | N39: 1 | O39: 1 | V39: =SUMPRODUCT(B39:U39*($B$16:$U$16="")) -> 13 | W39: =SUMPRODUCT($B39:$U39,$B$15:$U$15) -> 0
V40: =SUMPRODUCT(B40:U40*($B$16:$U$16="")) -> 0 | W40: =SUMPRODUCT($B40:$U40,$B$15:$U$15) -> 0
...

Sheet S5
A1: Season 5 · PlayFootball Old Street (5G, 6-a-side) · Oct 2025–Feb 2026
A2: Match | B2: GW1 | C2: GW2 | D2: GW3 | E2: GW4 | F2: GW5 | G2: GW6 | H2: GW7 | I2: GW8 | J2: GW9 | K2: GW10 | L2: GW11 | M2: GW12 | N2: GW13 | O2: GW14 | P2: GW15 | Q2: GW16 | R2: GW17 | S2: GW18 | T2: GW19 | U2: GW20 | X2: SEASON SUMMARY
A3: Date | B3: 45946 | C3: 45953 | D3: 45960 | E3: 45967 | F3: 45974 | G3: 45981 | H3: 45988 | I3: 45995 | J3: 46002 | K3: 46030 | L3: 46037 | M3: 46044 | N3: 46051 | O3: 46058 | X3: Played | Y3: =Y4+Y5+Y6 -> 13
A4: Kick-off | X4: Won | Y4: =SUMPRODUCT(($B$9:$U$9="W")*($B$16:$U$16="")) -> 2
A5: Opponent | B5: Dukes Select | C5: Green of the South | D5: Enjoy your mane Jane | E5: Old ivy | F5: Not Very often | G5: britannias | H5: DingCats | I5: Dukes | J5: Old ivy | K5: Enjoy | L5: Britannias | M5: Green of the South | N5: DingCats | O5: Not very often | X5: Drawn | Y5: =SUMPRODUCT(($B$9:$U$9="D")*($B$16:$U$16="")) -> 0
A6: Our goals | B6: 3 | C6: 0 | D6: 2 | E6: 1 | F6: 5 | G6: 1 | H6: 0 | I6: 8 | J6: 2 | K6: 1 | L6: 0 | M6: 2 | N6: 2 | O6: 10 | X6: Lost | Y6: =SUMPRODUCT(($B$9:$U$9="L")*($B$16:$U$16="")) -> 11
A7: Their goals | B7: 4 | C7: 2 | D7: 4 | E7: 6 | F7: 3 | G7: 4 | H7: 6 | I7: 0 | J7: 10 | K7: 6 | L7: 5 | M7: 10 | N7: 5 | O7: 5 | X7: Goals for | Y7: =SUMPRODUCT($B$6:$U$6*($B$16:$U$16="")) -> 29
A8: Score | B8: =IF(COUNT(B6:B7)<2,"",B6&"-"&B7) -> 3-4 | C8: =IF(COUNT(C6:C7)<2,"",C6&"-"&C7) -> 0-2 | D8: =IF(COUNT(D6:D7)<2,"",D6&"-"&D7) -> 2-4 | E8: =IF(COUNT(E6:E7)<2,"",E6&"-"&E7) -> 1-6 | F8: =IF(COUNT(F6:F7)<2,"",F6&"-"&F7) -> 5-3 | G8: =IF(COUNT(G6:G7)<2,"",G6&"-"&G7) -> 1-4 | H8: =IF(COUNT(H6:H7)<2,"",H6&"-"&H7) -> 0-6 | I8: =IF(COUNT(I6:I7)<2,"",I6&"-"&I7) -> 8-0 | ... U8: =IF(COUNT(U6:U7)<2,"",U6&"-"&U7) | X8: Goals against | Y8: =SUMPRODUCT($B$7:$U$7*($B$16:$U$16="")) -> 70
A9: Result | B9: =IF(COUNT(B6:B7)<2,"",IF(B6>B7,"W",IF(B6<B7,"L","D"))) -> L | C9: =IF(COUNT(C6:C7)<2,"",IF(C6>C7,"W",IF(C6<C7,"L","D"))) -> L | D9: =IF(COUNT(D6:D7)<2,"",IF(D6>D7,"W",IF(D6<D7,"L","D"))) -> L | E9: =IF(COUNT(E6:E7)<2,"",IF(E6>E7,"W",IF(E6<E7,"L","D"))) -> L | F9: =IF(COUNT(F6:F7)<2,"",IF(F6>F7,"W",IF(F6<F7,"L","D"))) -> W | G9: =IF(COUNT(G6:G7)<2,"",IF(G6>G7,"W",IF(G6<G7,"L","D"))) -> L | H9: =IF(COUNT(H6:H7)<2,"",IF(H6>H7,"W",IF(H6<H7,"L","D"))) -> L | I9: =IF(COUNT(I6:I7)<2,"",IF(I6>I7,"W",IF(I6<I7,"L","D"))) -> W | ... U9: =IF(COUNT(U6:U7)<2,"",IF(U6>U7,"W",IF(U6<U7,"L","D"))) | X9: Top scorer | Y9: {=IF(MAX($V$49:$V$76)=0,"—",INDEX($A$49:$A$76,MATCH(MAX($V$49:$V$76),$V$49:$V$76,0))&" ("&MAX($V$49:$V$76)&")")} -> Seb Burgess (10)
A10: MOTM | K10: Isaac Mond | L10: Phil Knott | M10: Seb Burgess | N10: Jake Ringer | O10: Eddie Ringer | X10: Most apps | Y10: {=IF(MAX($V$18:$V$45)=0,"—",INDEX($A$18:$A$45,MATCH(MAX($V$18:$V$45),$V$18:$V$45,0))&" ("&MAX($V$18:$V$45)&")")} -> Max Cobain (12)
A11: Champagne moment | X11: Season cost | Y11: =SUM($B$13:$U$13) -> 0
A12: Comments | I12: Forfeit | X12: Paid by
A13: Match cost (£)
A14: Players in game | B14: =COUNT(B$18:B$45) -> 8 | C14: =COUNT(C$18:C$45) -> 5 | D14: =COUNT(D$18:D$45) -> 6 | E14: =COUNT(E$18:E$45) -> 7 | F14: =COUNT(F$18:F$45) -> 6 | G14: =COUNT(G$18:G$45) -> 5 | H14: =COUNT(H$18:H$45) -> 7 | I14: =COUNT(I$18:I$45) -> 0 | ... U14: =COUNT(U$18:U$45) -> 0
A15: Cost per player (£) | B15: =IF(B$14=0,0,N(B$13)/B$14) -> 0 | C15: =IF(C$14=0,0,N(C$13)/C$14) -> 0 | D15: =IF(D$14=0,0,N(D$13)/D$14) -> 0 | E15: =IF(E$14=0,0,N(E$13)/E$14) -> 0 | F15: =IF(F$14=0,0,N(F$13)/F$14) -> 0 | G15: =IF(G$14=0,0,N(G$13)/G$14) -> 0 | H15: =IF(H$14=0,0,N(H$13)/H$14) -> 0 | I15: =IF(I$14=0,0,N(I$13)/I$14) -> 0 | ... U15: =IF(U$14=0,0,N(U$13)/U$14) -> 0
A16: Type (excl. from records) | I16: Forfeit
A17: APPEARANCES (1 = played) | B17: GW1 | C17: GW2 | D17: GW3 | E17: GW4 | F17: GW5 | G17: GW6 | H17: GW7 | I17: GW8 | J17: GW9 | K17: GW10 | L17: GW11 | M17: GW12 | N17: GW13 | O17: GW14 | P17: GW15 | Q17: GW16 | R17: GW17 | S17: GW18 | T17: GW19 | U17: GW20 | V17: Apps | W17: Cost (£)
A18: Ahmed | V18: =SUMPRODUCT(B18:U18*($B$16:$U$16="")) -> 0 | W18: =SUMPRODUCT($B18:$U18,$B$15:$U$15) -> 0
A19: Alex Ruben | E19: 1 | V19: =SUMPRODUCT(B19:U19*($B$16:$U$16="")) -> 1 | W19: =SUMPRODUCT($B19:$U19,$B$15:$U$15) -> 0
A20: Andy Cowan | B20: 1 | C20: 1 | D20: 1 | E20: 1 | F20: 1 | G20: 1 | H20: 1 | J20: 1 | V20: =SUMPRODUCT(B20:U20*($B$16:$U$16="")) -> 8 | W20: =SUMPRODUCT($B20:$U20,$B$15:$U$15) -> 0
A21: Ben Merrett | K21: 1 | V21: =SUMPRODUCT(B21:U21*($B$16:$U$16="")) -> 1 | W21: =SUMPRODUCT($B21:$U21,$B$15:$U$15) -> 0
A22: Callum McCarthy | V22: =SUMPRODUCT(B22:U22*($B$16:$U$16="")) -> 0 | W22: =SUMPRODUCT($B22:$U22,$B$15:$U$15) -> 0
A23: Cecil Watson | E23: 1 | V23: =SUMPRODUCT(B23:U23*($B$16:$U$16="")) -> 1 | W23: =SUMPRODUCT($B23:$U23,$B$15:$U$15) -> 0
A24: Conall Templeman | V24: =SUMPRODUCT(B24:U24*($B$16:$U$16="")) -> 0 | W24: =SUMPRODUCT($B24:$U24,$B$15:$U$15) -> 0
A25: Eddie Ringer | O25: 1 | V25: =SUMPRODUCT(B25:U25*($B$16:$U$16="")) -> 1 | W25: =SUMPRODUCT($B25:$U25,$B$15:$U$15) -> 0
A26: Finn Cawley | E26: 1 | V26: =SUMPRODUCT(B26:U26*($B$16:$U$16="")) -> 1 | W26: =SUMPRODUCT($B26:$U26,$B$15:$U$15) -> 0
A27: George Barbantan | B27: 1 | D27: 1 | E27: 1 | F27: 1 | G27: 1 | H27: 1 | J27: 1 | M27: 1 | N27: 1 | O27: 1 | V27: =SUMPRODUCT(B27:U27*($B$16:$U$16="")) -> 10 | W27: =SUMPRODUCT($B27:$U27,$B$15:$U$15) -> 0
A28: Henry Linklater | H28: 1 | V28: =SUMPRODUCT(B28:U28*($B$16:$U$16="")) -> 1 | W28: =SUMPRODUCT($B28:$U28,$B$15:$U$15) -> 0
A29: Isaac Mond | B29: 1 | C29: 1 | J29: 1 | K29: 1 | L29: 1 | M29: 1 | N29: 1 | O29: 1 | V29: =SUMPRODUCT(B29:U29*($B$16:$U$16="")) -> 8 | W29: =SUMPRODUCT($B29:$U29,$B$15:$U$15) -> 0
A30: Jake Harrison | V30: =SUMPRODUCT(B30:U30*($B$16:$U$16="")) -> 0 | W30: =SUMPRODUCT($B30:$U30,$B$15:$U$15) -> 0
A31: Jake Ringer | N31: 1 | V31: =SUMPRODUCT(B31:U31*($B$16:$U$16="")) -> 1 | W31: =SUMPRODUCT($B31:$U31,$B$15:$U$15) -> 0
A32: Keshav Singh | V32: =SUMPRODUCT(B32:U32*($B$16:$U$16="")) -> 0 | W32: =SUMPRODUCT($B32:$U32,$B$15:$U$15) -> 0
A33: Mark Pellowe | V33: =SUMPRODUCT(B33:U33*($B$16:$U$16="")) -> 0 | W33: =SUMPRODUCT($B33:$U33,$B$15:$U$15) -> 0
A34: Max Cobain | B34: 1 | C34: 1 | D34: 1 | E34: 1 | F34: 1 | G34: 1 | H34: 1 | J34: 1 | K34: 1 | L34: 1 | N34: 1 | O34: 1 | V34: =SUMPRODUCT(B34:U34*($B$16:$U$16="")) -> 12 | W34: =SUMPRODUCT($B34:$U34,$B$15:$U$15) -> 0
A35: Neeraj Radia | B35: 1 | D35: 1 | J35: 1 | K35: 1 | L35: 1 | M35: 1 | O35: 1 | V35: =SUMPRODUCT(B35:U35*($B$16:$U$16="")) -> 7 | W35: =SUMPRODUCT($B35:$U35,$B$15:$U$15) -> 0
A36: Phil Knott | B36: 1 | C36: 1 | D36: 1 | F36: 1 | H36: 1 | K36: 1 | L36: 1 | M36: 1 | N36: 1 | V36: =SUMPRODUCT(B36:U36*($B$16:$U$16="")) -> 9 | W36: =SUMPRODUCT($B36:$U36,$B$15:$U$15) -> 0
A37: Robin | V37: =SUMPRODUCT(B37:U37*($B$16:$U$16="")) -> 0 | W37: =SUMPRODUCT($B37:$U37,$B$15:$U$15) -> 0
A38: Sam Holt | B38: 1 | C38: 1 | D38: 1 | E38: 1 | F38: 1 | G38: 1 | H38: 1 | J38: 1 | K38: 1 | L38: 1 | O38: 1 | V38: =SUMPRODUCT(B38:U38*($B$16:$U$16="")) -> 11 | W38: =SUMPRODUCT($B38:$U38,$B$15:$U$15) -> 0
A39: Seb Burgess | B39: 1 | F39: 1 | G39: 1 | H39: 1 | J39: 1 | K39: 1 | M39: 1 | N39: 1 | O39: 1 | V39: =SUMPRODUCT(B39:U39*($B$16:$U$16="")) -> 9 | W39: =SUMPRODUCT($B39:$U39,$B$15:$U$15) -> 0
V40: =SUMPRODUCT(B40:U40*($B$16:$U$16="")) -> 0 | W40: =SUMPRODUCT($B40:$U40,$B$15:$U$15) -> 0
...

Sheet S6
A1: Season 6 · PlayFootball Old Street (5G, 6-a-side) · Feb–May 2026
A2: Match | B2: GW1 | C2: GW2 | D2: GW3 | E2: GW4 | F2: GW5 | G2: GW6 | H2: GW7 | I2: GW8 | J2: GW9 | K2: GW10 | L2: GW11 | M2: GW12 | N2: GW13 | O2: GW14 | P2: GW15 | Q2: GW16 | R2: GW17 | S2: GW18 | T2: GW19 | U2: GW20 | X2: SEASON SUMMARY
A3: Date | B3: 46065 | C3: 46072 | D3: 46079 | E3: 46086 | F3: 46093 | G3: 46100 | H3: 46107 | I3: 46114 | J3: 46121 | K3: 46128 | L3: 46135 | M3: 46142 | N3: 46149 | O3: 46156 | X3: Played | Y3: =Y4+Y5+Y6 -> 14
A4: Kick-off | X4: Won | Y4: =SUMPRODUCT(($B$9:$U$9="W")*($B$16:$U$16="")) -> 2
A5: Opponent | B5: Mane Jane | C5: MOB FC | D5: Cottesmore FC | E5: Green of the South | F5: Vauban FC | G5: The Britannias | H5: Old Ivy FC | I5: MOB FC | J5: enjoy your mane | K5: Vauban FC | L5: The Britannias | M5: Green of the South | N5: Old Ivy | O5: Cottesmore | X5: Drawn | Y5: =SUMPRODUCT(($B$9:$U$9="D")*($B$16:$U$16="")) -> 2
A6: Our goals | B6: 3 | C6: 8 | D6: 4 | E6: 3 | F6: 2 | G6: 0 | H6: 2 | I6: 4 | J6: 2 | K6: 6 | L6: 1 | M6: 3 | N6: 7 | O6: 2 | X6: Lost | Y6: =SUMPRODUCT(($B$9:$U$9="L")*($B$16:$U$16="")) -> 10
A7: Their goals | B7: 11 | C7: 2 | D7: 7 | E7: 3 | F7: 8 | G7: 6 | H7: 11 | I7: 6 | J7: 2 | K7: 4 | L7: 11 | M7: 7 | N7: 16 | O7: 7 | X7: Goals for | Y7: =SUMPRODUCT($B$6:$U$6*($B$16:$U$16="")) -> 47
A8: Score | B8: =IF(COUNT(B6:B7)<2,"",B6&"-"&B7) -> 3-11 | C8: =IF(COUNT(C6:C7)<2,"",C6&"-"&C7) -> 8-2 | D8: =IF(COUNT(D6:D7)<2,"",D6&"-"&D7) -> 4-7 | E8: =IF(COUNT(E6:E7)<2,"",E6&"-"&E7) -> 3-3 | F8: =IF(COUNT(F6:F7)<2,"",F6&"-"&F7) -> 2-8 | G8: =IF(COUNT(G6:G7)<2,"",G6&"-"&G7) -> 0-6 | H8: =IF(COUNT(H6:H7)<2,"",H6&"-"&H7) -> 2-11 | I8: =IF(COUNT(I6:I7)<2,"",I6&"-"&I7) -> 4-6 | ... U8: =IF(COUNT(U6:U7)<2,"",U6&"-"&U7) | X8: Goals against | Y8: =SUMPRODUCT($B$7:$U$7*($B$16:$U$16="")) -> 101
A9: Result | B9: =IF(COUNT(B6:B7)<2,"",IF(B6>B7,"W",IF(B6<B7,"L","D"))) -> L | C9: =IF(COUNT(C6:C7)<2,"",IF(C6>C7,"W",IF(C6<C7,"L","D"))) -> W | D9: =IF(COUNT(D6:D7)<2,"",IF(D6>D7,"W",IF(D6<D7,"L","D"))) -> L | E9: =IF(COUNT(E6:E7)<2,"",IF(E6>E7,"W",IF(E6<E7,"L","D"))) -> D | F9: =IF(COUNT(F6:F7)<2,"",IF(F6>F7,"W",IF(F6<F7,"L","D"))) -> L | G9: =IF(COUNT(G6:G7)<2,"",IF(G6>G7,"W",IF(G6<G7,"L","D"))) -> L | H9: =IF(COUNT(H6:H7)<2,"",IF(H6>H7,"W",IF(H6<H7,"L","D"))) -> L | I9: =IF(COUNT(I6:I7)<2,"",IF(I6>I7,"W",IF(I6<I7,"L","D"))) -> L | ... U9: =IF(COUNT(U6:U7)<2,"",IF(U6>U7,"W",IF(U6<U7,"L","D"))) | X9: Top scorer | Y9: {=IF(MAX($V$49:$V$76)=0,"—",INDEX($A$49:$A$76,MATCH(MAX($V$49:$V$76),$V$49:$V$76,0))&" ("&MAX($V$49:$V$76)&")")} -> Seb Burgess (15)
A10: MOTM | C10: Phil Knott | X10: Most apps | Y10: {=IF(MAX($V$18:$V$45)=0,"—",INDEX($A$18:$A$45,MATCH(MAX($V$18:$V$45),$V$18:$V$45,0))&" ("&MAX($V$18:$V$45)&")")} -> Seb Burgess (13)
A11: Champagne moment | X11: Season cost | Y11: =SUM($B$13:$U$13) -> 0
A12: Comments | X12: Paid by
A13: Match cost (£)
A14: Players in game | B14: =COUNT(B$18:B$45) -> 3 | C14: =COUNT(C$18:C$45) -> 5 | D14: =COUNT(D$18:D$45) -> 4 | E14: =COUNT(E$18:E$45) -> 7 | F14: =COUNT(F$18:F$45) -> 7 | G14: =COUNT(G$18:G$45) -> 6 | H14: =COUNT(H$18:H$45) -> 7 | I14: =COUNT(I$18:I$45) -> 7 | ... U14: =COUNT(U$18:U$45) -> 0
A15: Cost per player (£) | B15: =IF(B$14=0,0,N(B$13)/B$14) -> 0 | C15: =IF(C$14=0,0,N(C$13)/C$14) -> 0 | D15: =IF(D$14=0,0,N(D$13)/D$14) -> 0 | E15: =IF(E$14=0,0,N(E$13)/E$14) -> 0 | F15: =IF(F$14=0,0,N(F$13)/F$14) -> 0 | G15: =IF(G$14=0,0,N(G$13)/G$14) -> 0 | H15: =IF(H$14=0,0,N(H$13)/H$14) -> 0 | I15: =IF(I$14=0,0,N(I$13)/I$14) -> 0 | ... U15: =IF(U$14=0,0,N(U$13)/U$14) -> 0
A16: Type (excl. from records)
A17: APPEARANCES (1 = played) | B17: GW1 | C17: GW2 | D17: GW3 | E17: GW4 | F17: GW5 | G17: GW6 | H17: GW7 | I17: GW8 | J17: GW9 | K17: GW10 | L17: GW11 | M17: GW12 | N17: GW13 | O17: GW14 | P17: GW15 | Q17: GW16 | R17: GW17 | S17: GW18 | T17: GW19 | U17: GW20 | V17: Apps | W17: Cost (£)
A18: Ahmed | V18: =SUMPRODUCT(B18:U18*($B$16:$U$16="")) -> 0 | W18: =SUMPRODUCT($B18:$U18,$B$15:$U$15) -> 0
A19: Alex Ruben | V19: =SUMPRODUCT(B19:U19*($B$16:$U$16="")) -> 0 | W19: =SUMPRODUCT($B19:$U19,$B$15:$U$15) -> 0
A20: Andy Cowan | V20: =SUMPRODUCT(B20:U20*($B$16:$U$16="")) -> 0 | W20: =SUMPRODUCT($B20:$U20,$B$15:$U$15) -> 0
A21: Ben Merrett | F21: 1 | H21: 1 | I21: 1 | K21: 1 | M21: 1 | N21: 1 | V21: =SUMPRODUCT(B21:U21*($B$16:$U$16="")) -> 6 | W21: =SUMPRODUCT($B21:$U21,$B$15:$U$15) -> 0
A22: Callum McCarthy | V22: =SUMPRODUCT(B22:U22*($B$16:$U$16="")) -> 0 | W22: =SUMPRODUCT($B22:$U22,$B$15:$U$15) -> 0
A23: Cecil Watson | V23: =SUMPRODUCT(B23:U23*($B$16:$U$16="")) -> 0 | W23: =SUMPRODUCT($B23:$U23,$B$15:$U$15) -> 0
A24: Conall Templeman | L24: 1 | M24: 1 | N24: 1 | V24: =SUMPRODUCT(B24:U24*($B$16:$U$16="")) -> 3 | W24: =SUMPRODUCT($B24:$U24,$B$15:$U$15) -> 0
A25: Eddie Ringer | C25: 1 | V25: =SUMPRODUCT(B25:U25*($B$16:$U$16="")) -> 1 | W25: =SUMPRODUCT($B25:$U25,$B$15:$U$15) -> 0
A26: Finn Cawley | B26: 1 | H26: 1 | M26: 1 | V26: =SUMPRODUCT(B26:U26*($B$16:$U$16="")) -> 3 | W26: =SUMPRODUCT($B26:$U26,$B$15:$U$15) -> 0
A27: George Barbantan | V27: =SUMPRODUCT(B27:U27*($B$16:$U$16="")) -> 0 | W27: =SUMPRODUCT($B27:$U27,$B$15:$U$15) -> 0
A28: Henry Linklater | V28: =SUMPRODUCT(B28:U28*($B$16:$U$16="")) -> 0 | W28: =SUMPRODUCT($B28:$U28,$B$15:$U$15) -> 0
A29: Isaac Mond | E29: 1 | F29: 1 | G29: 1 | L29: 1 | N29: 1 | O29: 1 | V29: =SUMPRODUCT(B29:U29*($B$16:$U$16="")) -> 6 | W29: =SUMPRODUCT($B29:$U29,$B$15:$U$15) -> 0
A30: Jake Harrison | V30: =SUMPRODUCT(B30:U30*($B$16:$U$16="")) -> 0 | W30: =SUMPRODUCT($B30:$U30,$B$15:$U$15) -> 0
A31: Jake Ringer | C31: 1 | G31: 1 | V31: =SUMPRODUCT(B31:U31*($B$16:$U$16="")) -> 2 | W31: =SUMPRODUCT($B31:$U31,$B$15:$U$15) -> 0
A32: Keshav Singh | D32: 1 | E32: 1 | F32: 1 | G32: 1 | I32: 1 | J32: 1 | K32: 1 | L32: 1 | O32: 1 | V32: =SUMPRODUCT(B32:U32*($B$16:$U$16="")) -> 9 | W32: =SUMPRODUCT($B32:$U32,$B$15:$U$15) -> 0
A33: Mark Pellowe | D33: 1 | E33: 1 | F33: 1 | G33: 1 | H33: 1 | I33: 1 | J33: 1 | K33: 1 | L33: 1 | M33: 1 | N33: 1 | O33: 1 | V33: =SUMPRODUCT(B33:U33*($B$16:$U$16="")) -> 12 | W33: =SUMPRODUCT($B33:$U33,$B$15:$U$15) -> 0
A34: Max Cobain | C34: 1 | E34: 1 | G34: 1 | H34: 1 | I34: 1 | J34: 1 | K34: 1 | M34: 1 | N34: 1 | O34: 1 | V34: =SUMPRODUCT(B34:U34*($B$16:$U$16="")) -> 10 | W34: =SUMPRODUCT($B34:$U34,$B$15:$U$15) -> 0
A35: Neeraj Radia | H35: 1 | J35: 1 | N35: 1 | O35: 1 | V35: =SUMPRODUCT(B35:U35*($B$16:$U$16="")) -> 4 | W35: =SUMPRODUCT($B35:$U35,$B$15:$U$15) -> 0
A36: Phil Knott | B36: 1 | C36: 1 | E36: 1 | F36: 1 | H36: 1 | I36: 1 | J36: 1 | K36: 1 | M36: 1 | O36: 1 | V36: =SUMPRODUCT(B36:U36*($B$16:$U$16="")) -> 10 | W36: =SUMPRODUCT($B36:$U36,$B$15:$U$15) -> 0
A37: Robin | V37: =SUMPRODUCT(B37:U37*($B$16:$U$16="")) -> 0 | W37: =SUMPRODUCT($B37:$U37,$B$15:$U$15) -> 0
A38: Sam Holt | D38: 1 | E38: 1 | F38: 1 | H38: 1 | I38: 1 | J38: 1 | K38: 1 | V38: =SUMPRODUCT(B38:U38*($B$16:$U$16="")) -> 7 | W38: =SUMPRODUCT($B38:$U38,$B$15:$U$15) -> 0
A39: Seb Burgess | B39: 1 | C39: 1 | D39: 1 | E39: 1 | F39: 1 | G39: 1 | I39: 1 | J39: 1 | K39: 1 | L39: 1 | M39: 1 | N39: 1 | O39: 1 | V39: =SUMPRODUCT(B39:U39*($B$16:$U$16="")) -> 13 | W39: =SUMPRODUCT($B39:$U39,$B$15:$U$15) -> 0
V40: =SUMPRODUCT(B40:U40*($B$16:$U$16="")) -> 0 | W40: =SUMPRODUCT($B40:$U40,$B$15:$U$15) -> 0
...

Sheet S7
A1: Season 7 · PlayFootball Old Street (5G, 6-a-side) · May–Aug 2026 · imported from the team app
A2: Match | B2: GW1 | C2: GW2 | D2: GW3 | E2: GW4 | F2: GW5 | G2: GW6 | H2: GW7 | I2: GW8 | J2: GW9 | K2: GW10 | L2: GW11 | M2: GW12 | N2: GW13 | O2: GW14 | P2: GW15 | Q2: GW16 | R2: GW17 | S2: GW18 | T2: GW19 | U2: GW20 | X2: SEASON SUMMARY
A3: Date | B3: 46163 | C3: 46170 | D3: 46170 | E3: 46177 | F3: 46184 | G3: 46191 | H3: 46200 | I3: 46205 | J3: 46219 | K3: 46227 | L3: 46227 | M3: 46233 | N3: 46240 | O3: 46247 | P3: 46255 | X3: Played | Y3: =Y4+Y5+Y6 -> 11
A4: Kick-off | X4: Won | Y4: =SUMPRODUCT(($B$9:$U$9="W")*($B$16:$U$16="")) -> 3
A5: Opponent | B5: Enjoy your Mane Jane | C5: Recessionary FC | D5: Ref's Mates | E5: XZR FC | F5: Green of the South | G5: Vauban FC | H5: The Britannias | I5: Oly Ivy | J5: Enjoy your mane Jane | K5: Forfeit | L5: Vauban FC | M5: The Britannias | N5: Green of the South | O5: Old Ivy | P5: Xzr Fc | X5: Drawn | Y5: =SUMPRODUCT(($B$9:$U$9="D")*($B$16:$U$16="")) -> 0
A6: Our goals | B6: 3 | C6: 8 | D6: 7 | E6: 4 | F6: 2 | G6: 5 | H6: 1 | I6: 2 | J6: 0 | K6: 8 | L6: 6 | M6: 4 | N6: 3 | O6: 4 | P6: 6 | X6: Lost | Y6: =SUMPRODUCT(($B$9:$U$9="L")*($B$16:$U$16="")) -> 8
A7: Their goals | B7: 6 | C7: 0 | D7: 5 | E7: 2 | F7: 11 | G7: 4 | H7: 11 | I7: 6 | J7: 8 | K7: 0 | L7: 10 | M7: 6 | N7: 9 | O7: 8 | P7: 1 | X7: Goals for | Y7: =SUMPRODUCT($B$6:$U$6*($B$16:$U$16="")) -> 40
A8: Score | B8: =IF(COUNT(B6:B7)<2,"",B6&"-"&B7) -> 3-6 | C8: =IF(COUNT(C6:C7)<2,"",C6&"-"&C7) -> 8-0 | D8: =IF(COUNT(D6:D7)<2,"",D6&"-"&D7) -> 7-5 | E8: =IF(COUNT(E6:E7)<2,"",E6&"-"&E7) -> 4-2 | F8: =IF(COUNT(F6:F7)<2,"",F6&"-"&F7) -> 2-11 | G8: =IF(COUNT(G6:G7)<2,"",G6&"-"&G7) -> 5-4 | H8: =IF(COUNT(H6:H7)<2,"",H6&"-"&H7) -> 1-11 | I8: =IF(COUNT(I6:I7)<2,"",I6&"-"&I7) -> 2-6 | ... U8: =IF(COUNT(U6:U7)<2,"",U6&"-"&U7) | X8: Goals against | Y8: =SUMPRODUCT($B$7:$U$7*($B$16:$U$16="")) -> 74
A9: Result | B9: =IF(COUNT(B6:B7)<2,"",IF(B6>B7,"W",IF(B6<B7,"L","D"))) -> L | C9: =IF(COUNT(C6:C7)<2,"",IF(C6>C7,"W",IF(C6<C7,"L","D"))) -> W | D9: =IF(COUNT(D6:D7)<2,"",IF(D6>D7,"W",IF(D6<D7,"L","D"))) -> W | E9: =IF(COUNT(E6:E7)<2,"",IF(E6>E7,"W",IF(E6<E7,"L","D"))) -> W | F9: =IF(COUNT(F6:F7)<2,"",IF(F6>F7,"W",IF(F6<F7,"L","D"))) -> L | G9: =IF(COUNT(G6:G7)<2,"",IF(G6>G7,"W",IF(G6<G7,"L","D"))) -> W | H9: =IF(COUNT(H6:H7)<2,"",IF(H6>H7,"W",IF(H6<H7,"L","D"))) -> L | I9: =IF(COUNT(I6:I7)<2,"",IF(I6>I7,"W",IF(I6<I7,"L","D"))) -> L | ... U9: =IF(COUNT(U6:U7)<2,"",IF(U6>U7,"W",IF(U6<U7,"L","D"))) | X9: Top scorer | Y9: {=IF(MAX($V$49:$V$76)=0,"—",INDEX($A$49:$A$76,MATCH(MAX($V$49:$V$76),$V$49:$V$76,0))&" ("&MAX($V$49:$V$76)&")")} -> Ahmed (5)
A10: MOTM | X10: Most apps | Y10: {=IF(MAX($V$18:$V$45)=0,"—",INDEX($A$18:$A$45,MATCH(MAX($V$18:$V$45),$V$18:$V$45,0))&" ("&MAX($V$18:$V$45)&")")} -> Mark Pellowe (11)
A11: Champagne moment | X11: Season cost | Y11: =SUM($B$13:$U$13) -> 0
A12: Comments | C12: Forfeit | D12: Friendly | J12: Forfeit | K12: Forfeit | X12: Paid by
A13: Match cost (£)
A14: Players in game | B14: =COUNT(B$18:B$45) -> 7 | C14: =COUNT(C$18:C$45) -> 0 | D14: =COUNT(D$18:D$45) -> 7 | E14: =COUNT(E$18:E$45) -> 6 | F14: =COUNT(F$18:F$45) -> 6 | G14: =COUNT(G$18:G$45) -> 7 | H14: =COUNT(H$18:H$45) -> 5 | I14: =COUNT(I$18:I$45) -> 7 | ... U14: =COUNT(U$18:U$45) -> 0
A15: Cost per player (£) | B15: =IF(B$14=0,0,N(B$13)/B$14) -> 0 | C15: =IF(C$14=0,0,N(C$13)/C$14) -> 0 | D15: =IF(D$14=0,0,N(D$13)/D$14) -> 0 | E15: =IF(E$14=0,0,N(E$13)/E$14) -> 0 | F15: =IF(F$14=0,0,N(F$13)/F$14) -> 0 | G15: =IF(G$14=0,0,N(G$13)/G$14) -> 0 | H15: =IF(H$14=0,0,N(H$13)/H$14) -> 0 | I15: =IF(I$14=0,0,N(I$13)/I$14) -> 0 | ... U15: =IF(U$14=0,0,N(U$13)/U$14) -> 0
A16: Type (excl. from records) | C16: Forfeit | D16: Friendly | J16: Forfeit | K16: Forfeit
A17: APPEARANCES (1 = played) | B17: GW1 | C17: GW2 | D17: GW3 | E17: GW4 | F17: GW5 | G17: GW6 | H17: GW7 | I17: GW8 | J17: GW9 | K17: GW10 | L17: GW11 | M17: GW12 | N17: GW13 | O17: GW14 | P17: GW15 | Q17: GW16 | R17: GW17 | S17: GW18 | T17: GW19 | U17: GW20 | V17: Apps | W17: Cost (£)
A18: Ahmed | H18: 1 | M18: 1 | O18: 1 | V18: =SUMPRODUCT(B18:U18*($B$16:$U$16="")) -> 3 | W18: =SUMPRODUCT($B18:$U18,$B$15:$U$15) -> 0
A19: Alex Ruben | V19: =SUMPRODUCT(B19:U19*($B$16:$U$16="")) -> 0 | W19: =SUMPRODUCT($B19:$U19,$B$15:$U$15) -> 0
A20: Andy Cowan | V20: =SUMPRODUCT(B20:U20*($B$16:$U$16="")) -> 0 | W20: =SUMPRODUCT($B20:$U20,$B$15:$U$15) -> 0
A21: Ben Merrett | B21: 1 | D21: 1 | G21: 1 | H21: 1 | I21: 1 | L21: 1 | O21: 1 | V21: =SUMPRODUCT(B21:U21*($B$16:$U$16="")) -> 6 | W21: =SUMPRODUCT($B21:$U21,$B$15:$U$15) -> 0
A22: Callum McCarthy | V22: =SUMPRODUCT(B22:U22*($B$16:$U$16="")) -> 0 | W22: =SUMPRODUCT($B22:$U22,$B$15:$U$15) -> 0
A23: Cecil Watson | V23: =SUMPRODUCT(B23:U23*($B$16:$U$16="")) -> 0 | W23: =SUMPRODUCT($B23:$U23,$B$15:$U$15) -> 0
A24: Conall Templeman | B24: 1 | D24: 1 | E24: 1 | F24: 1 | G24: 1 | H24: 1 | I24: 1 | L24: 1 | P24: 1 | V24: =SUMPRODUCT(B24:U24*($B$16:$U$16="")) -> 8 | W24: =SUMPRODUCT($B24:$U24,$B$15:$U$15) -> 0
A25: Eddie Ringer | O25: 1 | V25: =SUMPRODUCT(B25:U25*($B$16:$U$16="")) -> 1 | W25: =SUMPRODUCT($B25:$U25,$B$15:$U$15) -> 0
A26: Finn Cawley | D26: 1 | G26: 1 | L26: 1 | V26: =SUMPRODUCT(B26:U26*($B$16:$U$16="")) -> 2 | W26: =SUMPRODUCT($B26:$U26,$B$15:$U$15) -> 0
A27: George Barbantan | L27: 1 | M27: 1 | O27: 1 | V27: =SUMPRODUCT(B27:U27*($B$16:$U$16="")) -> 3 | W27: =SUMPRODUCT($B27:$U27,$B$15:$U$15) -> 0
A28: Henry Linklater | V28: =SUMPRODUCT(B28:U28*($B$16:$U$16="")) -> 0 | W28: =SUMPRODUCT($B28:$U28,$B$15:$U$15) -> 0
A29: Isaac Mond | B29: 1 | D29: 1 | I29: 1 | N29: 1 | O29: 1 | V29: =SUMPRODUCT(B29:U29*($B$16:$U$16="")) -> 4 | W29: =SUMPRODUCT($B29:$U29,$B$15:$U$15) -> 0
A30: Jake Harrison | V30: =SUMPRODUCT(B30:U30*($B$16:$U$16="")) -> 0 | W30: =SUMPRODUCT($B30:$U30,$B$15:$U$15) -> 0
A31: Jake Ringer | N31: 1 | V31: =SUMPRODUCT(B31:U31*($B$16:$U$16="")) -> 1 | W31: =SUMPRODUCT($B31:$U31,$B$15:$U$15) -> 0
A32: Keshav Singh | E32: 1 | F32: 1 | I32: 1 | L32: 1 | M32: 1 | V32: =SUMPRODUCT(B32:U32*($B$16:$U$16="")) -> 5 | W32: =SUMPRODUCT($B32:$U32,$B$15:$U$15) -> 0
A33: Mark Pellowe | B33: 1 | E33: 1 | F33: 1 | G33: 1 | H33: 1 | I33: 1 | L33: 1 | M33: 1 | N33: 1 | O33: 1 | P33: 1 | V33: =SUMPRODUCT(B33:U33*($B$16:$U$16="")) -> 11 | W33: =SUMPRODUCT($B33:$U33,$B$15:$U$15) -> 0
A34: Max Cobain | B34: 1 | D34: 1 | E34: 1 | F34: 1 | V34: =SUMPRODUCT(B34:U34*($B$16:$U$16="")) -> 3 | W34: =SUMPRODUCT($B34:$U34,$B$15:$U$15) -> 0
A35: Neeraj Radia | B35: 1 | D35: 1 | F35: 1 | G35: 1 | V35: =SUMPRODUCT(B35:U35*($B$16:$U$16="")) -> 3 | W35: =SUMPRODUCT($B35:$U35,$B$15:$U$15) -> 0
A36: Phil Knott | B36: 1 | E36: 1 | G36: 1 | H36: 1 | I36: 1 | M36: 1 | N36: 1 | O36: 1 | V36: =SUMPRODUCT(B36:U36*($B$16:$U$16="")) -> 8 | W36: =SUMPRODUCT($B36:$U36,$B$15:$U$15) -> 0
A37: Robin | V37: =SUMPRODUCT(B37:U37*($B$16:$U$16="")) -> 0 | W37: =SUMPRODUCT($B37:$U37,$B$15:$U$15) -> 0
A38: Sam Holt | V38: =SUMPRODUCT(B38:U38*($B$16:$U$16="")) -> 0 | W38: =SUMPRODUCT($B38:$U38,$B$15:$U$15) -> 0
A39: Seb Burgess | D39: 1 | E39: 1 | F39: 1 | G39: 1 | I39: 1 | V39: =SUMPRODUCT(B39:U39*($B$16:$U$16="")) -> 4 | W39: =SUMPRODUCT($B39:$U39,$B$15:$U$15) -> 0
V40: =SUMPRODUCT(B40:U40*($B$16:$U$16="")) -> 0 | W40: =SUMPRODUCT($B40:$U40,$B$15:$U$15) -> 0
...

Sheet S8
A1: Season 8 · Whitechapel Tuesday 6’s — Premier League · Sep 2026–Jan 2027
A2: Match | B2: GW1 | C2: GW2 | D2: GW3 | E2: GW4 | F2: GW5 | G2: GW6 | H2: GW7 | I2: GW8 | J2: GW9 | K2: GW10 | L2: GW11 | M2: GW12 | N2: GW13 | O2: GW14 | P2: GW15 | Q2: GW16 | R2: GW17 | S2: GW18 | T2: GW19 | U2: GW20 | X2: SEASON SUMMARY
A3: Date | B3: 46266 | C3: 46273 | D3: 46280 | E3: 46287 | F3: 46294 | G3: 46301 | H3: 46308 | I3: 46315 | J3: 46322 | K3: 46329 | L3: 46336 | M3: 46343 | N3: 46350 | O3: 46357 | P3: 46364 | Q3: 46371 | R3: 46392 | S3: 46399 | X3: Played | Y3: =Y4+Y5+Y6 -> 1
A4: Kick-off | B4: 0.81597222 | C4: 0.84375 | D4: 0.76041667 | E4: 0.87152778 | F4: 0.76041667 | G4: 0.76041667 | H4: 0.87152778 | I4: 0.87152778 | J4: 0.78819444 | K4: 0.81597222 | L4: 0.76041667 | M4: 0.84375 | N4: 0.84375 | O4: 0.84375 | P4: 0.78819444 | Q4: 0.87152778 | R4: 0.76041667 | S4: 0.76041667 | X4: Won | Y4: =SUMPRODUCT(($B$9:$U$9="W")*($B$16:$U$16="")) -> 0
A5: Opponent | B5: Spartak High Press, Low Standards | C5: Inter Islington | D5: TMHLR F.C. | E5: Heavy MWEtal Football | F5: Thundering Trunks | G5: Corsicans FC | H5: Monaco Goalkickers | I5: ABHUS FC | J5: MATHOL FC | K5: Spartak High Press, Low Standards | L5: Inter Islington | M5: TMHLR F.C. | N5: Heavy MWEtal Football | O5: Thundering Trunks | P5: Corsicans FC | Q5: Monaco Goalkickers | R5: ABHUS FC | S5: MATHOL FC | X5: Drawn | Y5: =SUMPRODUCT(($B$9:$U$9="D")*($B$16:$U$16="")) -> 0
A6: Our goals | B6: 5 | X6: Lost | Y6: =SUMPRODUCT(($B$9:$U$9="L")*($B$16:$U$16="")) -> 1
A7: Their goals | B7: 7 | X7: Goals for | Y7: =SUMPRODUCT($B$6:$U$6*($B$16:$U$16="")) -> 5
A8: Score | B8: =IF(COUNT(B6:B7)<2,"",B6&"-"&B7) -> 5-7 | C8: =IF(COUNT(C6:C7)<2,"",C6&"-"&C7) | D8: =IF(COUNT(D6:D7)<2,"",D6&"-"&D7) | E8: =IF(COUNT(E6:E7)<2,"",E6&"-"&E7) | F8: =IF(COUNT(F6:F7)<2,"",F6&"-"&F7) | G8: =IF(COUNT(G6:G7)<2,"",G6&"-"&G7) | H8: =IF(COUNT(H6:H7)<2,"",H6&"-"&H7) | I8: =IF(COUNT(I6:I7)<2,"",I6&"-"&I7) | ... U8: =IF(COUNT(U6:U7)<2,"",U6&"-"&U7) | X8: Goals against | Y8: =SUMPRODUCT($B$7:$U$7*($B$16:$U$16="")) -> 7
A9: Result | B9: =IF(COUNT(B6:B7)<2,"",IF(B6>B7,"W",IF(B6<B7,"L","D"))) -> L | C9: =IF(COUNT(C6:C7)<2,"",IF(C6>C7,"W",IF(C6<C7,"L","D"))) | D9: =IF(COUNT(D6:D7)<2,"",IF(D6>D7,"W",IF(D6<D7,"L","D"))) | E9: =IF(COUNT(E6:E7)<2,"",IF(E6>E7,"W",IF(E6<E7,"L","D"))) | F9: =IF(COUNT(F6:F7)<2,"",IF(F6>F7,"W",IF(F6<F7,"L","D"))) | G9: =IF(COUNT(G6:G7)<2,"",IF(G6>G7,"W",IF(G6<G7,"L","D"))) | H9: =IF(COUNT(H6:H7)<2,"",IF(H6>H7,"W",IF(H6<H7,"L","D"))) | I9: =IF(COUNT(I6:I7)<2,"",IF(I6>I7,"W",IF(I6<I7,"L","D"))) | ... U9: =IF(COUNT(U6:U7)<2,"",IF(U6>U7,"W",IF(U6<U7,"L","D"))) | X9: Top scorer | Y9: {=IF(MAX($V$49:$V$76)=0,"—",INDEX($A$49:$A$76,MATCH(MAX($V$49:$V$76),$V$49:$V$76,0))&" ("&MAX($V$49:$V$76)&")")} -> Seb Burgess (3)
A10: MOTM | X10: Most apps | Y10: {=IF(MAX($V$18:$V$45)=0,"—",INDEX($A$18:$A$45,MATCH(MAX($V$18:$V$45),$V$18:$V$45,0))&" ("&MAX($V$18:$V$45)&")")} -> Ben Merrett (1)
A11: Champagne moment | X11: Season cost | Y11: =SUM($B$13:$U$13) -> 1439.1
A12: Comments | X12: Paid by | Y12: Isaac Mond
A13: Match cost (£) | B13: 79.95 | C13: 79.95 | D13: 79.95 | E13: 79.95 | F13: 79.95 | G13: 79.95 | H13: 79.95 | I13: 79.95 | J13: 79.95 | K13: 79.95 | L13: 79.95 | M13: 79.95 | N13: 79.95 | O13: 79.95 | P13: 79.95 | Q13: 79.95 | R13: 79.95 | S13: 79.95
A14: Players in game | B14: =COUNT(B$18:B$45) -> 7 | C14: =COUNT(C$18:C$45) -> 0 | D14: =COUNT(D$18:D$45) -> 0 | E14: =COUNT(E$18:E$45) -> 0 | F14: =COUNT(F$18:F$45) -> 0 | G14: =COUNT(G$18:G$45) -> 0 | H14: =COUNT(H$18:H$45) -> 0 | I14: =COUNT(I$18:I$45) -> 0 | ... U14: =COUNT(U$18:U$45) -> 0
A15: Cost per player (£) | B15: =IF(B$14=0,0,N(B$13)/B$14) -> 11.421429 | C15: =IF(C$14=0,0,N(C$13)/C$14) -> 0 | D15: =IF(D$14=0,0,N(D$13)/D$14) -> 0 | E15: =IF(E$14=0,0,N(E$13)/E$14) -> 0 | F15: =IF(F$14=0,0,N(F$13)/F$14) -> 0 | G15: =IF(G$14=0,0,N(G$13)/G$14) -> 0 | H15: =IF(H$14=0,0,N(H$13)/H$14) -> 0 | I15: =IF(I$14=0,0,N(I$13)/I$14) -> 0 | ... U15: =IF(U$14=0,0,N(U$13)/U$14) -> 0
A16: Type (excl. from records)
A17: APPEARANCES (1 = played) | B17: GW1 | C17: GW2 | D17: GW3 | E17: GW4 | F17: GW5 | G17: GW6 | H17: GW7 | I17: GW8 | J17: GW9 | K17: GW10 | L17: GW11 | M17: GW12 | N17: GW13 | O17: GW14 | P17: GW15 | Q17: GW16 | R17: GW17 | S17: GW18 | T17: GW19 | U17: GW20 | V17: Apps | W17: Cost (£)
A18: Ahmed | V18: =SUMPRODUCT(B18:U18*($B$16:$U$16="")) -> 0 | W18: =SUMPRODUCT($B18:$U18,$B$15:$U$15) -> 0
A19: Alex Ruben | V19: =SUMPRODUCT(B19:U19*($B$16:$U$16="")) -> 0 | W19: =SUMPRODUCT($B19:$U19,$B$15:$U$15) -> 0
A20: Andy Cowan | V20: =SUMPRODUCT(B20:U20*($B$16:$U$16="")) -> 0 | W20: =SUMPRODUCT($B20:$U20,$B$15:$U$15) -> 0
A21: Ben Merrett | B21: 1 | V21: =SUMPRODUCT(B21:U21*($B$16:$U$16="")) -> 1 | W21: =SUMPRODUCT($B21:$U21,$B$15:$U$15) -> 11.421429
A22: Callum McCarthy | V22: =SUMPRODUCT(B22:U22*($B$16:$U$16="")) -> 0 | W22: =SUMPRODUCT($B22:$U22,$B$15:$U$15) -> 0
A23: Cecil Watson | V23: =SUMPRODUCT(B23:U23*($B$16:$U$16="")) -> 0 | W23: =SUMPRODUCT($B23:$U23,$B$15:$U$15) -> 0
A24: Conall Templeman | V24: =SUMPRODUCT(B24:U24*($B$16:$U$16="")) -> 0 | W24: =SUMPRODUCT($B24:$U24,$B$15:$U$15) -> 0
A25: Eddie Ringer | V25: =SUMPRODUCT(B25:U25*($B$16:$U$16="")) -> 0 | W25: =SUMPRODUCT($B25:$U25,$B$15:$U$15) -> 0
A26: Finn Cawley | B26: 1 | V26: =SUMPRODUCT(B26:U26*($B$16:$U$16="")) -> 1 | W26: =SUMPRODUCT($B26:$U26,$B$15:$U$15) -> 11.421429
A27: George Barbantan | V27: =SUMPRODUCT(B27:U27*($B$16:$U$16="")) -> 0 | W27: =SUMPRODUCT($B27:$U27,$B$15:$U$15) -> 0
A28: Henry Linklater | V28: =SUMPRODUCT(B28:U28*($B$16:$U$16="")) -> 0 | W28: =SUMPRODUCT($B28:$U28,$B$15:$U$15) -> 0
A29: Isaac Mond | B29: 1 | V29: =SUMPRODUCT(B29:U29*($B$16:$U$16="")) -> 1 | W29: =SUMPRODUCT($B29:$U29,$B$15:$U$15) -> 11.421429
A30: Jake Harrison | V30: =SUMPRODUCT(B30:U30*($B$16:$U$16="")) -> 0 | W30: =SUMPRODUCT($B30:$U30,$B$15:$U$15) -> 0
A31: Jake Ringer | V31: =SUMPRODUCT(B31:U31*($B$16:$U$16="")) -> 0 | W31: =SUMPRODUCT($B31:$U31,$B$15:$U$15) -> 0
A32: Keshav Singh | B32: 1 | V32: =SUMPRODUCT(B32:U32*($B$16:$U$16="")) -> 1 | W32: =SUMPRODUCT($B32:$U32,$B$15:$U$15) -> 11.421429
A33: Mark Pellowe | V33: =SUMPRODUCT(B33:U33*($B$16:$U$16="")) -> 0 | W33: =SUMPRODUCT($B33:$U33,$B$15:$U$15) -> 0
A34: Max Cobain | B34: 1 | V34: =SUMPRODUCT(B34:U34*($B$16:$U$16="")) -> 1 | W34: =SUMPRODUCT($B34:$U34,$B$15:$U$15) -> 11.421429
A35: Neeraj Radia | V35: =SUMPRODUCT(B35:U35*($B$16:$U$16="")) -> 0 | W35: =SUMPRODUCT($B35:$U35,$B$15:$U$15) -> 0
A36: Phil Knott | B36: 1 | V36: =SUMPRODUCT(B36:U36*($B$16:$U$16="")) -> 1 | W36: =SUMPRODUCT($B36:$U36,$B$15:$U$15) -> 11.421429
A37: Robin | V37: =SUMPRODUCT(B37:U37*($B$16:$U$16="")) -> 0 | W37: =SUMPRODUCT($B37:$U37,$B$15:$U$15) -> 0
A38: Sam Holt | V38: =SUMPRODUCT(B38:U38*($B$16:$U$16="")) -> 0 | W38: =SUMPRODUCT($B38:$U38,$B$15:$U$15) -> 0
A39: Seb Burgess | B39: 1 | V39: =SUMPRODUCT(B39:U39*($B$16:$U$16="")) -> 1 | W39: =SUMPRODUCT($B39:$U39,$B$15:$U$15) -> 11.421429
V40: =SUMPRODUCT(B40:U40*($B$16:$U$16="")) -> 0 | W40: =SUMPRODUCT($B40:$U40,$B$15:$U$15) -> 0
...

Sheet Season template
A1: SEASON TEMPLATE — duplicate this tab, rename it (e.g. S9), fill in fixtures
A2: Match | B2: GW1 | C2: GW2 | D2: GW3 | E2: GW4 | F2: GW5 | G2: GW6 | H2: GW7 | I2: GW8 | J2: GW9 | K2: GW10 | L2: GW11 | M2: GW12 | N2: GW13 | O2: GW14 | P2: GW15 | Q2: GW16 | R2: GW17 | S2: GW18 | T2: GW19 | U2: GW20 | X2: SEASON SUMMARY
A3: Date | X3: Played | Y3: =Y4+Y5+Y6 -> 0
A4: Kick-off | X4: Won | Y4: =SUMPRODUCT(($B$9:$U$9="W")*($B$16:$U$16="")) -> 0
A5: Opponent | X5: Drawn | Y5: =SUMPRODUCT(($B$9:$U$9="D")*($B$16:$U$16="")) -> 0
A6: Our goals | X6: Lost | Y6: =SUMPRODUCT(($B$9:$U$9="L")*($B$16:$U$16="")) -> 0
A7: Their goals | X7: Goals for | Y7: =SUMPRODUCT($B$6:$U$6*($B$16:$U$16="")) -> 0
